Workbook

Sheet pol-CX
A1: Table 6 from CNOT-Optimal Clifford Synthesis as SAT
AC2: \begin{table}[h!]
AC3: \setlength\tabcolsep{2pt}
AC4: \fontfamily{lmss}\fontsize{8}{9}\selectfont{
AC5: \begin{center}
B6: without permutation | I6: with permutation | AC6: \begin{tabular}{ |l| | AD6: r| | AE6: r| | AF6: r| | AG6: r| | AH6: r| | AI6: r| | AJ6: r| | AK6: r| | AL6: r| | AM6: r| | AN6: r|} | AO6: \hline
A7: Tool: | B7: tket | C7: qmap | E7: qsynth-f | G7: qsynth-b | I7: tket | J7: qsynth-f | L7: qsynth-b | Q7: =I7 -> tket | R7: =J7 -> qsynth-f | T7: =L7 -> qsynth-b | V7: Optimal | X7: AStar-100 | Z7: Greedy | AC7: =P7&"&" -> & | AD7: ="\textbf{"&Q7&"}&" -> \textbf{tket}& | AE7: ="\multicolumn{2}{|l|}{\textbf{"&R7&"}}&" -> \multicolumn{2}{|l|}{\textbf{qsynth-f}}& | AG7: ="\multicolumn{2}{|l|}{\textbf{"&T7&"}}&" -> \multicolumn{2}{|l|}{\textbf{qsynth-b}}& | AI7: ="\multicolumn{2}{|l|}{\textbf{"&V7&"}}&" -> \multicolumn{2}{|l|}{\textbf{Optimal}}& | AK7: ="\multicolumn{2}{|l|}{\textbf{"&X7&"}}&" -> \multicolumn{2}{|l|}{\textbf{AStar-100}}& | AM7: ="\multicolumn{2}{|l|}{\textbf{"&Z7&"}}\\" -> \multicolumn{2}{|l|}{\textbf{Greedy}}\\ | AO7: \hline
A8: instance | B8: m | C8: m | D8: t | E8: m | F8: t | G8: m | H8: t | I8: m | J8: m | K8: t | L8: m | M8: t | P8: =A8 -> instance | Q8: =I8 -> m | R8: =J8 -> m | S8: =K8 -> t | T8: =L8 -> m | U8: =M8 -> t | V8: m | W8: t | X8: m | Y8: t | Z8: m | AA8: t | AC8: ="\textbf{"&P8&"}&" -> \textbf{instance}& | AD8: ="\textbf{"&Q8&"}&" -> \textbf{m}& | AE8: ="\textbf{"&R8&"}&" -> \textbf{m}& | AF8: ="\textbf{"&S8&"}&" -> \textbf{t}& | AG8: ="\textbf{"&T8&"}&" -> \textbf{m}& | AH8: ="\textbf{"&U8&"}&" -> \textbf{t}& | AI8: ="\textbf{"&V8&"}&" -> \textbf{m}& | AJ8: ="\textbf{"&W8&"}&" -> \textbf{t}& | ... AM8: ="\textbf{"&Z8&"}&" -> \textbf{m}& | AN8: ="\textbf{"&AA8&"}\\" -> \textbf{t}\\ | AO8: \hline
A9: 3q05306 | B9: 4 | C9: 4 | D9: 1452.5 | E9: 4 | F9: 0.13 | G9: 4 | H9: 0.06 | I9: 2 | J9: 2 | K9: 0.1 | L9: 2 | M9: 0.09 | P9: =A9 -> 3q05306 | Q9: =I9 -> 2 | R9: =J9 -> 2 | S9: =K9 -> 0.1 | T9: =L9 -> 2 | U9: =M9 -> 0.09 | V9: =summ!AD11 -> 2 | W9: =summ!AR11 -> 0.010961708 | X9: =summ!R11 -> 2 | Y9: =summ!AF11 -> 0.36817837 | Z9: =summ!T11 -> 2 | AA9: =summ!AH11 -> 0.30444326 | AC9: =P9&"&" -> 3q05306& | AD9: =Q9&"&" -> 2& | AE9: =R9&"&" -> 2& | AF9: =TEXT(S9,"0.0E+00")&"&" -> 1.0E-01& | AG9: =T9&"&" -> 2& | AH9: =TEXT(U9,"0.0E+00")&"&" -> 9.0E-02& | AI9: =V9&"&" -> 2& | AJ9: =TEXT(W9,"0.0E+00")&"&" -> 1.1E-02& | AK9: =X9&"&" -> 2& | AL9: =TEXT(Y9,"0.0E+00")&"&" -> 3.7E-01& | AM9: =Z9&"&" -> 2& | AN9: =TEXT(AA9,"0.0E+00")&"\\" -> 3.0E-01\\
A10: 3q33936 | B10: 3 | C10: 3 | D10: 29.3 | E10: 3 | F10: 0.07 | G10: 3 | H10: 0.05 | I10: 3 | J10: 3 | K10: 0.07 | L10: 3 | M10: 0.06 | P10: =A10 -> 3q33936 | Q10: =I10 -> 3 | R10: =J10 -> 3 | S10: =K10 -> 0.07 | T10: =L10 -> 3 | U10: =M10 -> 0.06 | V10: =summ!AD12 -> 3 | W10: =summ!AR12 -> 0.001359125 | X10: =summ!R12 -> 3 | Y10: =summ!AF12 -> 0.00496018 | Z10: =summ!T12 -> 3 | AA10: =summ!AH12 -> 0.006433622 | AC10: =P10&"&" -> 3q33936& | AD10: =Q10&"&" -> 3& | AE10: =R10&"&" -> 3& | AF10: =TEXT(S10,"0.0E+00")&"&" -> 7.0E-02& | AG10: =T10&"&" -> 3& | AH10: =TEXT(U10,"0.0E+00")&"&" -> 6.0E-02& | AI10: =V10&"&" -> 3& | AJ10: =TEXT(W10,"0.0E+00")&"&" -> 1.4E-03& | AK10: =X10&"&" -> 3& | AL10: =TEXT(Y10,"0.0E+00")&"&" -> 5.0E-03& | AM10: =Z10&"&" -> 3& | AN10: =TEXT(AA10,"0.0E+00")&"\\" -> 6.4E-03\\
A11: 3q50494 | B11: 4 | C11: 4 | D11: 1804.7 | E11: 4 | F11: 0.08 | G11: 4 | H11: 0.05 | I11: 3 | J11: 3 | K11: 0.06 | L11: 3 | M11: 0.05 | P11: =A11 -> 3q50494 | Q11: =I11 -> 3 | R11: =J11 -> 3 | S11: =K11 -> 0.06 | T11: =L11 -> 3 | U11: =M11 -> 0.05 | V11: =summ!AD13 -> 3 | W11: =summ!AR13 -> 0.001352333 | X11: =summ!R13 -> 3 | Y11: =summ!AF13 -> 0.004834851 | Z11: =summ!T13 -> 3 | AA11: =summ!AH13 -> 0.006156026 | AC11: =P11&"&" -> 3q50494& | AD11: =Q11&"&" -> 3& | AE11: =R11&"&" -> 3& | AF11: =TEXT(S11,"0.0E+00")&"&" -> 6.0E-02& | AG11: =T11&"&" -> 3& | AH11: =TEXT(U11,"0.0E+00")&"&" -> 5.0E-02& | AI11: =V11&"&" -> 3& | AJ11: =TEXT(W11,"0.0E+00")&"&" -> 1.4E-03& | AK11: =X11&"&" -> 3& | AL11: =TEXT(Y11,"0.0E+00")&"&" -> 4.8E-03& | AM11: =Z11&"&" -> 3& | AN11: =TEXT(AA11,"0.0E+00")&"\\" -> 6.2E-03\\
A12: 3q55125 | B12: 3 | C12: 3 | D12: 77.2 | E12: 3 | F12: 0.06 | G12: 3 | H12: 0.04 | I12: 3 | J12: 3 | K12: 0.06 | L12: 3 | M12: 0.05 | P12: =A12 -> 3q55125 | Q12: =I12 -> 3 | R12: =J12 -> 3 | S12: =K12 -> 0.06 | T12: =L12 -> 3 | U12: =M12 -> 0.05 | V12: =summ!AD14 -> 3 | W12: =summ!AR14 -> 0.001281958 | X12: =summ!R14 -> 3 | Y12: =summ!AF14 -> 0.004870141 | Z12: =summ!T14 -> 3 | AA12: =summ!AH14 -> 0.006390825 | AC12: =P12&"&" -> 3q55125& | AD12: =Q12&"&" -> 3& | AE12: =R12&"&" -> 3& | AF12: =TEXT(S12,"0.0E+00")&"&" -> 6.0E-02& | AG12: =T12&"&" -> 3& | AH12: =TEXT(U12,"0.0E+00")&"&" -> 5.0E-02& | AI12: =V12&"&" -> 3& | AJ12: =TEXT(W12,"0.0E+00")&"&" -> 1.3E-03& | AK12: =X12&"&" -> 3& | AL12: =TEXT(Y12,"0.0E+00")&"&" -> 4.9E-03& | AM12: =Z12&"&" -> 3& | AN12: =TEXT(AA12,"0.0E+00")&"\\" -> 6.4E-03\\
A13: 3q99346 | B13: 4 | C13: 4 | D13: 1650.2 | E13: 4 | F13: 0.08 | G13: 4 | H13: 0.05 | I13: 3 | J13: 3 | K13: 0.06 | L13: 3 | M13: 0.05 | P13: =A13 -> 3q99346 | Q13: =I13 -> 3 | R13: =J13 -> 3 | S13: =K13 -> 0.06 | T13: =L13 -> 3 | U13: =M13 -> 0.05 | V13: =summ!AD15 -> 3 | W13: =summ!AR15 -> 0.001065917 | X13: =summ!R15 -> 3 | Y13: =summ!AF15 -> 0.004942298 | Z13: =summ!T15 -> 3 | AA13: =summ!AH15 -> 0.006314003 | AC13: =P13&"&" -> 3q99346& | AD13: =Q13&"&" -> 3& | AE13: =R13&"&" -> 3& | AF13: =TEXT(S13,"0.0E+00")&"&" -> 6.0E-02& | AG13: =T13&"&" -> 3& | AH13: =TEXT(U13,"0.0E+00")&"&" -> 5.0E-02& | AI13: =V13&"&" -> 3& | AJ13: =TEXT(W13,"0.0E+00")&"&" -> 1.1E-03& | AK13: =X13&"&" -> 3& | AL13: =TEXT(Y13,"0.0E+00")&"&" -> 4.9E-03& | AM13: =Z13&"&" -> 3& | AN13: =TEXT(AA13,"0.0E+00")&"\\" -> 6.3E-03\\
A14: 4q05306 | B14: 6 | C14: - | D14: TO | E14: 6 | F14: 0.2 | G14: 6 | H14: 0.12 | I14: 6 | J14: 5 | K14: 0.44 | L14: 5 | M14: 0.5 | P14: =A14 -> 4q05306 | Q14: =I14 -> 6 | R14: =J14 -> 5 | S14: =K14 -> 0.44 | T14: =L14 -> 5 | U14: =M14 -> 0.5 | V14: =summ!AD16 -> 5 | W14: =summ!AR16 -> 0.002832666 | X14: =summ!R16 -> 5 | Y14: =summ!AF16 -> 0.20923711 | Z14: =summ!T16 -> 5 | AA14: =summ!AH16 -> 0.019167533 | AC14: =P14&"&" -> 4q05306& | AD14: =Q14&"&" -> 6& | AE14: =R14&"&" -> 5& | AF14: =TEXT(S14,"0.0E+00")&"&" -> 4.4E-01& | AG14: =T14&"&" -> 5& | AH14: =TEXT(U14,"0.0E+00")&"&" -> 5.0E-01& | AI14: =V14&"&" -> 5& | AJ14: =TEXT(W14,"0.0E+00")&"&" -> 2.8E-03& | AK14: =X14&"&" -> 5& | AL14: =TEXT(Y14,"0.0E+00")&"&" -> 2.1E-01& | AM14: =Z14&"&" -> 5& | AN14: =TEXT(AA14,"0.0E+00")&"\\" -> 1.9E-02\\
A15: 4q33936 | B15: 8 | C15: - | D15: TO | E15: 6 | F15: 0.38 | G15: 6 | H15: 0.31 | I15: 8 | J15: 5 | K15: 0.35 | L15: 5 | M15: 0.71 | P15: =A15 -> 4q33936 | Q15: =I15 -> 8 | R15: =J15 -> 5 | S15: =K15 -> 0.35 | T15: =L15 -> 5 | U15: =M15 -> 0.71 | V15: =summ!AD17 -> 5 | W15: =summ!AR17 -> 0.001150459 | X15: =summ!R17 -> 5 | Y15: =summ!AF17 -> 0.20583972 | Z15: =summ!T17 -> 5 | AA15: =summ!AH17 -> 0.016144929 | AC15: =P15&"&" -> 4q33936& | AD15: =Q15&"&" -> 8& | AE15: =R15&"&" -> 5& | AF15: =TEXT(S15,"0.0E+00")&"&" -> 3.5E-01& | AG15: =T15&"&" -> 5& | AH15: =TEXT(U15,"0.0E+00")&"&" -> 7.1E-01& | AI15: =V15&"&" -> 5& | AJ15: =TEXT(W15,"0.0E+00")&"&" -> 1.2E-03& | AK15: =X15&"&" -> 5& | AL15: =TEXT(Y15,"0.0E+00")&"&" -> 2.1E-01& | AM15: =Z15&"&" -> 5& | AN15: =TEXT(AA15,"0.0E+00")&"\\" -> 1.6E-02\\
A16: 4q50494 | B16: 7 | C16: - | D16: TO | E16: 7 | F16: 0.49 | G16: 7 | H16: 0.38 | I16: 4 | J16: 4 | K16: 0.1 | L16: 4 | M16: 0.07 | P16: =A16 -> 4q50494 | Q16: =I16 -> 4 | R16: =J16 -> 4 | S16: =K16 -> 0.1 | T16: =L16 -> 4 | U16: =M16 -> 0.07 | V16: =summ!AD18 -> 4 | W16: =summ!AR18 -> 0.001172459 | X16: =summ!R18 -> 4 | Y16: =summ!AF18 -> 0.008700126 | Z16: =summ!T18 -> 4 | AA16: =summ!AH18 -> 0.010180927 | AC16: =P16&"&" -> 4q50494& | AD16: =Q16&"&" -> 4& | AE16: =R16&"&" -> 4& | AF16: =TEXT(S16,"0.0E+00")&"&" -> 1.0E-01& | AG16: =T16&"&" -> 4& | AH16: =TEXT(U16,"0.0E+00")&"&" -> 7.0E-02& | AI16: =V16&"&" -> 4& | AJ16: =TEXT(W16,"0.0E+00")&"&" -> 1.2E-03& | AK16: =X16&"&" -> 4& | AL16: =TEXT(Y16,"0.0E+00")&"&" -> 8.7E-03& | AM16: =Z16&"&" -> 4& | AN16: =TEXT(AA16,"0.0E+00")&"\\" -> 1.0E-02\\
A17: 4q55125 | B17: 6 | C17: - | D17: TO | E17: 6 | F17: 0.18 | G17: 6 | H17: 0.11 | I17: 6 | J17: 5 | K17: 0.43 | L17: 5 | M17: 0.33 | P17: =A17 -> 4q55125 | Q17: =I17 -> 6 | R17: =J17 -> 5 | S17: =K17 -> 0.43 | T17: =L17 -> 5 | U17: =M17 -> 0.33 | V17: =summ!AD19 -> 5 | W17: =summ!AR19 -> 0.001124417 | X17: =summ!R19 -> 5 | Y17: =summ!AF19 -> 0.20000194 | Z17: =summ!T19 -> 6 | AA17: =summ!AH19 -> 0.019910293 | AC17: =P17&"&" -> 4q55125& | AD17: =Q17&"&" -> 6& | AE17: =R17&"&" -> 5& | AF17: =TEXT(S17,"0.0E+00")&"&" -> 4.3E-01& | AG17: =T17&"&" -> 5& | AH17: =TEXT(U17,"0.0E+00")&"&" -> 3.3E-01& | AI17: =V17&"&" -> 5& | AJ17: =TEXT(W17,"0.0E+00")&"&" -> 1.1E-03& | AK17: =X17&"&" -> 5& | AL17: =TEXT(Y17,"0.0E+00")&"&" -> 2.0E-01& | AM17: =Z17&"&" -> 6& | AN17: =TEXT(AA17,"0.0E+00")&"\\" -> 2.0E-02\\
A18: 4q99346 | B18: 7 | C18: - | D18: TO | E18: 5 | F18: 0.19 | G18: 5 | H18: 0.25 | I18: 6 | J18: 5 | K18: 0.43 | L18: 5 | M18: 0.35 | P18: =A18 -> 4q99346 | Q18: =I18 -> 6 | R18: =J18 -> 5 | S18: =K18 -> 0.43 | T18: =L18 -> 5 | U18: =M18 -> 0.35 | V18: =summ!AD20 -> 5 | W18: =summ!AR20 -> 0.001200708 | X18: =summ!R20 -> 5 | Y18: =summ!AF20 -> 0.21846146 | Z18: =summ!T20 -> 5 | AA18: =summ!AH20 -> 0.016706432 | AC18: =P18&"&" -> 4q99346& | AD18: =Q18&"&" -> 6& | AE18: =R18&"&" -> 5& | AF18: =TEXT(S18,"0.0E+00")&"&" -> 4.3E-01& | AG18: =T18&"&" -> 5& | AH18: =TEXT(U18,"0.0E+00")&"&" -> 3.5E-01& | AI18: =V18&"&" -> 5& | AJ18: =TEXT(W18,"0.0E+00")&"&" -> 1.2E-03& | AK18: =X18&"&" -> 5& | AL18: =TEXT(Y18,"0.0E+00")&"&" -> 2.2E-01& | AM18: =Z18&"&" -> 5& | AN18: =TEXT(AA18,"0.0E+00")&"\\" -> 1.7E-02\\
A19: 5q05306 | B19: 12 | C19: - | D19: TO | E19: 8 | F19: 4.74 | G19: 8 | H19: 14.1 | I19: 11 | J19: 8 | K19: 34.93 | L19: 8 | M19: 151.2 | P19: =A19 -> 5q05306 | Q19: =I19 -> 11 | R19: =J19 -> 8 | S19: =K19 -> 34.93 | T19: =L19 -> 8 | U19: =M19 -> 151.2 | V19: =summ!AD21 -> 8 | W19: =summ!AR21 -> 0.004948292 | X19: =summ!R21 -> 8 | Y19: =summ!AF21 -> 2.7661903 | Z19: =summ!T21 -> 8 | AA19: =summ!AH21 -> 0.035736832 | AC19: =P19&"&" -> 5q05306& | AD19: =Q19&"&" -> 11& | AE19: =R19&"&" -> 8& | AF19: =TEXT(S19,"0.0E+00")&"&" -> 3.5E+01& | AG19: =T19&"&" -> 8& | AH19: =TEXT(U19,"0.0E+00")&"&" -> 1.5E+02& | AI19: =V19&"&" -> 8& | AJ19: =TEXT(W19,"0.0E+00")&"&" -> 4.9E-03& | AK19: =X19&"&" -> 8& | AL19: =TEXT(Y19,"0.0E+00")&"&" -> 2.8E+00& | AM19: =Z19&"&" -> 8& | AN19: =TEXT(AA19,"0.0E+00")&"\\" -> 3.6E-02\\
A20: 5q33936 | B20: 13 | C20: - | D20: TO | E20: 9 | F20: 11.7 | G20: 9 | H20: 33.44 | I20: 10 | J20: 8 | K20: 34.35 | L20: 8 | M20: 126.5 | P20: =A20 -> 5q33936 | Q20: =I20 -> 10 | R20: =J20 -> 8 | S20: =K20 -> 34.35 | T20: =L20 -> 8 | U20: =M20 -> 126.5 | V20: =summ!AD22 -> 8 | W20: =summ!AR22 -> 0.003467667 | X20: =summ!R22 -> 8 | Y20: =summ!AF22 -> 2.6938772 | Z20: =summ!T22 -> 9 | AA20: =summ!AH22 -> 0.046923149 | AC20: =P20&"&" -> 5q33936& | AD20: =Q20&"&" -> 10& | AE20: =R20&"&" -> 8& | AF20: =TEXT(S20,"0.0E+00")&"&" -> 3.4E+01& | AG20: =T20&"&" -> 8& | AH20: =TEXT(U20,"0.0E+00")&"&" -> 1.3E+02& | AI20: =V20&"&" -> 8& | AJ20: =TEXT(W20,"0.0E+00")&"&" -> 3.5E-03& | AK20: =X20&"&" -> 8& | AL20: =TEXT(Y20,"0.0E+00")&"&" -> 2.7E+00& | AM20: =Z20&"&" -> 9& | AN20: =TEXT(AA20,"0.0E+00")&"\\" -> 4.7E-02\\
A21: 5q50494 | B21: 17 | C21: - | D21: TO | E21: 8 | F21: 4.03 | G21: 8 | H21: 36.89 | I21: 11 | J21: 7 | K21: 22.35 | L21: 7 | M21: 56.6 | P21: =A21 -> 5q50494 | Q21: =I21 -> 11 | R21: =J21 -> 7 | S21: =K21 -> 22.35 | T21: =L21 -> 7 | U21: =M21 -> 56.6 | V21: =summ!AD23 -> 7 | W21: =summ!AR23 -> 0.002966958 | X21: =summ!R23 -> 7 | Y21: =summ!AF23 -> 1.3997427 | Z21: =summ!T23 -> 8 | AA21: =summ!AH23 -> 0.036019432 | AC21: =P21&"&" -> 5q50494& | AD21: =Q21&"&" -> 11& | AE21: =R21&"&" -> 7& | AF21: =TEXT(S21,"0.0E+00")&"&" -> 2.2E+01& | AG21: =T21&"&" -> 7& | AH21: =TEXT(U21,"0.0E+00")&"&" -> 5.7E+01& | AI21: =V21&"&" -> 7& | AJ21: =TEXT(W21,"0.0E+00")&"&" -> 3.0E-03& | AK21: =X21&"&" -> 7& | AL21: =TEXT(Y21,"0.0E+00")&"&" -> 1.4E+00& | AM21: =Z21&"&" -> 8& | AN21: =TEXT(AA21,"0.0E+00")&"\\" -> 3.6E-02\\
A22: 5q55125 | B22: 13 | C22: - | D22: TO | E22: 9 | F22: 13.89 | G22: 9 | H22: 22.23 | I22: 9 | J22: 7 | K22: 4.49 | L22: 7 | M22: 9.25 | P22: =A22 -> 5q55125 | Q22: =I22 -> 9 | R22: =J22 -> 7 | S22: =K22 -> 4.49 | T22: =L22 -> 7 | U22: =M22 -> 9.25 | V22: =summ!AD24 -> 7 | W22: =summ!AR24 -> 0.002277292 | X22: =summ!R24 -> 7 | Y22: =summ!AF24 -> 1.6600286 | Z22: =summ!T24 -> 7 | AA22: =summ!AH24 -> 0.027744671 | AC22: =P22&"&" -> 5q55125& | AD22: =Q22&"&" -> 9& | AE22: =R22&"&" -> 7& | AF22: =TEXT(S22,"0.0E+00")&"&" -> 4.5E+00& | AG22: =T22&"&" -> 7& | AH22: =TEXT(U22,"0.0E+00")&"&" -> 9.3E+00& | AI22: =V22&"&" -> 7& | AJ22: =TEXT(W22,"0.0E+00")&"&" -> 2.3E-03& | AK22: =X22&"&" -> 7& | AL22: =TEXT(Y22,"0.0E+00")&"&" -> 1.7E+00& | AM22: =Z22&"&" -> 7& | AN22: =TEXT(AA22,"0.0E+00")&"\\" -> 2.8E-02\\
A23: 5q99346 | B23: 11 | C23: - | D23: TO | E23: 7 | F23: 1.05 | G23: 7 | H23: 2.86 | I23: 10 | J23: 6 | K23: 1.52 | L23: 6 | M23: 7.88 | P23: =A23 -> 5q99346 | Q23: =I23 -> 10 | R23: =J23 -> 6 | S23: =K23 -> 1.52 | T23: =L23 -> 6 | U23: =M23 -> 7.88 | V23: =summ!AD25 -> 6 | W23: =summ!AR25 -> 0.002303666 | X23: =summ!R25 -> 6 | Y23: =summ!AF25 -> 0.7357055 | Z23: =summ!T25 -> 6 | AA23: =summ!AH25 -> 0.026753869 | AC23: =P23&"&" -> 5q99346& | AD23: =Q23&"&" -> 10& | AE23: =R23&"&" -> 6& | AF23: =TEXT(S23,"0.0E+00")&"&" -> 1.5E+00& | AG23: =T23&"&" -> 6& | AH23: =TEXT(U23,"0.0E+00")&"&" -> 7.9E+00& | AI23: =V23&"&" -> 6& | AJ23: =TEXT(W23,"0.0E+00")&"&" -> 2.3E-03& | AK23: =X23&"&" -> 6& | AL23: =TEXT(Y23,"0.0E+00")&"&" -> 7.4E-01& | AM23: =Z23&"&" -> 6& | AN23: =TEXT(AA23,"0.0E+00")&"\\" -> 2.7E-02\\
A24: 6q05306 | B24: 15 | C24: - | D24: TO | E24: - | F24: TO | G24: 12 | H24: TO | I24: 15 | J24: 15 | K24: TO | L24: 11 | M24: TO | P24: =A24 -> 6q05306 | Q24: =I24 -> 15 | R24: =J24 -> 15 | S24: =K24 -> TO | T24: =L24 -> 11 | U24: =M24 -> TO | V24: - | W24: - | X24: =summ!R26 -> 11 | Y24: =summ!AF26 -> 6.8577902 | Z24: =summ!T26 -> 12 | AA24: =summ!AH26 -> 0.090180174 | AC24: =P24&"&" -> 6q05306& | AD24: =Q24&"&" -> 15& | AE24: =R24&"&" -> 15& | AF24: =TEXT(S24,"0.0E+00")&"&" -> TO& | AG24: =T24&"&" -> 11& | AH24: =TEXT(U24,"0.0E+00")&"&" -> TO& | AI24: =V24&"&" -> -& | AJ24: =TEXT(W24,"0.0E+00")&"&" -> -& | AK24: =X24&"&" -> 11& | AL24: =TEXT(Y24,"0.0E+00")&"&" -> 6.9E+00& | AM24: =Z24&"&" -> 12& | AN24: =TEXT(AA24,"0.0E+00")&"\\" -> 9.0E-02\\
A25: 6q33936 | B25: 20 | C25: - | D25: TO | E25: 11 | F25: 2017.7 | G25: 12 | H25: TO | I25: 14 | J25: 14 | K25: TO | L25: 11 | M25: TO | P25: =A25 -> 6q33936 | Q25: =I25 -> 14 | R25: =J25 -> 14 | S25: =K25 -> TO | T25: =L25 -> 11 | U25: =M25 -> TO | V25: - | W25: - | X25: =summ!R27 -> 10 | Y25: =summ!AF27 -> 5.779905 | Z25: =summ!T27 -> 12 | AA25: =summ!AH27 -> 0.098856311 | AC25: =P25&"&" -> 6q33936& | AD25: =Q25&"&" -> 14& | AE25: =R25&"&" -> 14& | AF25: =TEXT(S25,"0.0E+00")&"&" -> TO& | AG25: =T25&"&" -> 11& | AH25: =TEXT(U25,"0.0E+00")&"&" -> TO& | AI25: =V25&"&" -> -& | AJ25: =TEXT(W25,"0.0E+00")&"&" -> -& | AK25: =X25&"&" -> 10& | AL25: =TEXT(Y25,"0.0E+00")&"&" -> 5.8E+00& | AM25: =Z25&"&" -> 12& | AN25: =TEXT(AA25,"0.0E+00")&"\\" -> 9.9E-02\\
A26: 6q50494 | B26: 17 | C26: - | D26: TO | E26: 11 | F26: 964.3 | G26: 11 | H26: 4525.9 | I26: 14 | J26: 14 | K26: TO | L26: 12 | M26: TO | P26: =A26 -> 6q50494 | Q26: =I26 -> 14 | R26: =J26 -> 14 | S26: =K26 -> TO | T26: =L26 -> 12 | U26: =M26 -> TO | V26: - | W26: - | X26: =summ!R28 -> 11 | Y26: =summ!AF28 -> 6.6222814 | Z26: =summ!T28 -> 11 | AA26: =summ!AH28 -> 0.077395749 | AC26: =P26&"&" -> 6q50494& | AD26: =Q26&"&" -> 14& | AE26: =R26&"&" -> 14& | AF26: =TEXT(S26,"0.0E+00")&"&" -> TO& | AG26: =T26&"&" -> 12& | AH26: =TEXT(U26,"0.0E+00")&"&" -> TO& | AI26: =V26&"&" -> -& | AJ26: =TEXT(W26,"0.0E+00")&"&" -> -& | AK26: =X26&"&" -> 11& | AL26: =TEXT(Y26,"0.0E+00")&"&" -> 6.6E+00& | AM26: =Z26&"&" -> 11& | AN26: =TEXT(AA26,"0.0E+00")&"\\" -> 7.7E-02\\
A27: 6q55125 | B27: 18 | C27: - | D27: TO | E27: 11 | F27: 1060.2 | G27: 11 | H27: 5059.7 | I27: 14 | J27: 10 | K27: 6452.9 | L27: 10 | M27: TO | P27: =A27 -> 6q55125 | Q27: =I27 -> 14 | R27: =J27 -> 10 | S27: =K27 -> 6452.9 | T27: =L27 -> 10 | U27: =M27 -> TO | V27: - | W27: - | X27: =summ!R29 -> 10 | Y27: =summ!AF29 -> 5.7888678 | Z27: =summ!T29 -> 10 | AA27: =summ!AH29 -> 0.076236628 | AC27: =P27&"&" -> 6q55125& | AD27: =Q27&"&" -> 14& | AE27: =R27&"&" -> 10& | AF27: =TEXT(S27,"0.0E+00")&"&" -> 6.5E+03& | AG27: =T27&"&" -> 10& | AH27: =TEXT(U27,"0.0E+00")&"&" -> TO& | AI27: =V27&"&" -> -& | AJ27: =TEXT(W27,"0.0E+00")&"&" -> -& | AK27: =X27&"&" -> 10& | AL27: =TEXT(Y27,"0.0E+00")&"&" -> 5.8E+00& | AM27: =Z27&"&" -> 10& | AN27: =TEXT(AA27,"0.0E+00")&"\\" -> 7.6E-02\\
A28: 6q99346 | B28: 15 | C28: - | D28: TO | E28: - | F28: TO | G28: 12 | H28: TO | I28: 15 | J28: - | K28: TO | L28: 11 | M28: TO | P28: =A28 -> 6q99346 | Q28: =I28 -> 15 | R28: =J28 -> - | S28: =K28 -> TO | T28: =L28 -> 11 | U28: =M28 -> TO | V28: - | W28: - | X28: =summ!R30 -> 11 | Y28: =summ!AF30 -> 6.8123189 | Z28: =summ!T30 -> 11 | AA28: =summ!AH30 -> 0.084014047 | AC28: =P28&"&" -> 6q99346& | AD28: =Q28&"&" -> 15& | AE28: =R28&"&" -> -& | AF28: =TEXT(S28,"0.0E+00")&"&" -> TO& | AG28: =T28&"&" -> 11& | AH28: =TEXT(U28,"0.0E+00")&"&" -> TO& | AI28: =V28&"&" -> -& | AJ28: =TEXT(W28,"0.0E+00")&"&" -> -& | AK28: =X28&"&" -> 11& | AL28: =TEXT(Y28,"0.0E+00")&"&" -> 6.8E+00& | AM28: =Z28&"&" -> 11& | AN28: =TEXT(AA28,"0.0E+00")&"\\" -> 8.4E-02\\
A29: 7q05306 | B29: 25 | C29: - | D29: TO | E29: - | F29: TO | G29: - | H29: TO | I29: 24 | J29: - | K29: TO | L29: 19 | M29: TO | P29: =A29 -> 7q05306 | Q29: =I29 -> 24 | R29: =J29 -> - | S29: =K29 -> TO | T29: =L29 -> 19 | U29: =M29 -> TO | V29: - | W29: - | X29: =summ!R31 -> 15 | Y29: =summ!AF31 -> 14.010082 | Z29: =summ!T31 -> 16 | AA29: =summ!AH31 -> 0.16320194 | AC29: =P29&"&" -> 7q05306& | AD29: =Q29&"&" -> 24& | AE29: =R29&"&" -> -& | AF29: =TEXT(S29,"0.0E+00")&"&" -> TO& | AG29: =T29&"&" -> 19& | AH29: =TEXT(U29,"0.0E+00")&"&" -> TO& | AI29: =V29&"&" -> -& | AJ29: =TEXT(W29,"0.0E+00")&"&" -> -& | AK29: =X29&"&" -> 15& | AL29: =TEXT(Y29,"0.0E+00")&"&" -> 1.4E+01& | AM29: =Z29&"&" -> 16& | AN29: =TEXT(AA29,"0.0E+00")&"\\" -> 1.6E-01\\
A30: 7q33936 | B30: 24 | C30: - | D30: TO | E30: - | F30: TO | G30: - | H30: TO | I30: 20 | J30: - | K30: TO | L30: 17 | M30: TO | P30: =A30 -> 7q33936 | Q30: =I30 -> 20 | R30: =J30 -> - | S30: =K30 -> TO | T30: =L30 -> 17 | U30: =M30 -> TO | V30: - | W30: - | X30: =summ!R32 -> 14 | Y30: =summ!AF32 -> 13.545793 | Z30: =summ!T32 -> 16 | AA30: =summ!AH32 -> 0.16237427 | AC30: =P30&"&" -> 7q33936& | AD30: =Q30&"&" -> 20& | AE30: =R30&"&" -> -& | AF30: =TEXT(S30,"0.0E+00")&"&" -> TO& | AG30: =T30&"&" -> 17& | AH30: =TEXT(U30,"0.0E+00")&"&" -> TO& | AI30: =V30&"&" -> -& | AJ30: =TEXT(W30,"0.0E+00")&"&" -> -& | AK30: =X30&"&" -> 14& | AL30: =TEXT(Y30,"0.0E+00")&"&" -> 1.4E+01& | AM30: =Z30&"&" -> 16& | AN30: =TEXT(AA30,"0.0E+00")&"\\" -> 1.6E-01\\
A31: 7q50494 | B31: 22 | C31: - | D31: TO | E31: - | F31: TO | G31: 18 | H31: TO | I31: 20 | J31: - | K31: TO | L31: - | M31: TO | P31: =A31 -> 7q50494 | Q31: =I31 -> 20 | R31: =J31 -> - | S31: =K31 -> TO | T31: =L31 -> - | U31: =M31 -> TO | V31: - | W31: - | X31: =summ!R33 -> 14 | Y31: =summ!AF33 -> 13.191143 | Z31: =summ!T33 -> 17 | AA31: =summ!AH33 -> 0.17682188 | AC31: =P31&"&" -> 7q50494& | AD31: =Q31&"&" -> 20& | AE31: =R31&"&" -> -& | AF31: =TEXT(S31,"0.0E+00")&"&" -> TO& | AG31: =T31&"&" -> -& | AH31: =TEXT(U31,"0.0E+00")&"&" -> TO& | AI31: =V31&"&" -> -& | AJ31: =TEXT(W31,"0.0E+00")&"&" -> -& | AK31: =X31&"&" -> 14& | AL31: =TEXT(Y31,"0.0E+00")&"&" -> 1.3E+01& | AM31: =Z31&"&" -> 17& | AN31: =TEXT(AA31,"0.0E+00")&"\\" -> 1.8E-01\\
A32: 7q55125 | B32: 22 | C32: - | D32: TO | E32: - | F32: TO | G32: 17 | H32: TO | I32: 18 | J32: - | K32: TO | L32: 17 | M32: TO | P32: =A32 -> 7q55125 | Q32: =I32 -> 18 | R32: =J32 -> - | S32: =K32 -> TO | T32: =L32 -> 17 | U32: =M32 -> TO | V32: - | W32: - | X32: =summ!R34 -> 14 | Y32: =summ!AF34 -> 12.694247 | Z32: =summ!T34 -> 14 | AA32: =summ!AH34 -> 0.12401897 | AC32: =P32&"&" -> 7q55125& | AD32: =Q32&"&" -> 18& | AE32: =R32&"&" -> -& | AF32: =TEXT(S32,"0.0E+00")&"&" -> TO& | AG32: =T32&"&" -> 17& | AH32: =TEXT(U32,"0.0E+00")&"&" -> TO& | AI32: =V32&"&" -> -& | AJ32: =TEXT(W32,"0.0E+00")&"&" -> -& | AK32: =X32&"&" -> 14& | AL32: =TEXT(Y32,"0.0E+00")&"&" -> 1.3E+01& | AM32: =Z32&"&" -> 14& | AN32: =TEXT(AA32,"0.0E+00")&"\\" -> 1.2E-01\\
A33: 7q99346 | B33: 21 | C33: - | D33: TO | E33: - | F33: TO | G33: - | H33: TO | I33: 20 | J33: - | K33: TO | L33: 19 | M33: TO | P33: =A33 -> 7q99346 | Q33: =I33 -> 20 | R33: =J33 -> - | S33: =K33 -> TO | T33: =L33 -> 19 | U33: =M33 -> TO | V33: - | W33: - | X33: =summ!R35 -> 14 | Y33: =summ!AF35 -> 12.46988 | Z33: =summ!T35 -> 16 | AA33: =summ!AH35 -> 0.14270985 | AC33: =P33&"&" -> 7q99346& | AD33: =Q33&"&" -> 20& | AE33: =R33&"&" -> -& | AF33: =TEXT(S33,"0.0E+00")&"&" -> TO& | AG33: =T33&"&" -> 19& | AH33: =TEXT(U33,"0.0E+00")&"&" -> TO& | AI33: =V33&"&" -> -& | AJ33: =TEXT(W33,"0.0E+00")&"&" -> -& | AK33: =X33&"&" -> 14& | AL33: =TEXT(Y33,"0.0E+00")&"&" -> 1.2E+01& | AM33: =Z33&"&" -> 16& | AN33: =TEXT(AA33,"0.0E+00")&"\\" -> 1.4E-01\\ | AO33: \hline
AC34: \end{tabular}
Y35: =TEXT(Y33,"0.0E+00") -> 1.2E+01 | AC35: \end{table}

Sheet pol-depth
A1: imeout.
A2: without-permutation | B2: with-permutation
A3: Tool: | B3: tket | C3: qmap | D3: qsynth-f | E3: qsynth-b | F3: tket | G3: qsynth-f | H3: qsynth-b
A4: instance | B4: m | C4: m | D4: t | E4: m | F4: t | G4: m | H4: t | I4: m | J4: m | K4: t | L4: m | M4: t
A5: 3q05306 | B5: 4 | C5: 4 | D5: 0.4 | E5: 4 | F5: 0.13 | G5: 4 | H5: 0.06 | I5: 2 | J5: 2 | K5: 0.1 | L5: 2 | M5: 0.09
A6: 3q33936 | B6: 3 | C6: 3 | D6: 0.39 | E6: 3 | F6: 0.07 | G6: 3 | H6: 0.05 | I6: 3 | J6: 3 | K6: 0.07 | L6: 3 | M6: 0.05
A7: 3q50494 | B7: 4 | C7: 4 | D7: 0.25 | E7: 4 | F7: 0.08 | G7: 4 | H7: 0.05 | I7: 3 | J7: 3 | K7: 0.06 | L7: 3 | M7: 0.04
A8: 3q55125 | B8: 3 | C8: 3 | D8: 0.42 | E8: 3 | F8: 0.06 | G8: 3 | H8: 0.04 | I8: 3 | J8: 3 | K8: 0.06 | L8: 3 | M8: 0.05
A9: 3q99346 | B9: 4 | C9: 4 | D9: 0.34 | E9: 4 | F9: 0.08 | G9: 4 | H9: 0.05 | I9: 3 | J9: 3 | K9: 0.06 | L9: 3 | M9: 0.05
A10: 4q05306 | B10: 4 | C10: 5 | D10: 4 | E10: 4 | F10: 0.11 | G10: 4 | H10: 0.07 | I10: 4 | J10: 3 | K10: 0.12 | L10: 3 | M10: 0.1
A11: 4q33936 | B11: 7 | C11: 5 | D11: 4.27 | E11: 4 | F11: 0.16 | G11: 4 | H11: 0.34 | I11: 7 | J11: 3 | K11: 0.14 | L11: 3 | M11: 0.57
A12: 4q50494 | B12: 6 | C12: 6 | D12: 6.85 | E12: 4 | F12: 0.17 | G12: 4 | H12: 0.17 | I12: 3 | J12: 3 | K12: 0.07 | L12: 3 | M12: 0.05
A13: 4q55125 | B13: 4 | C13: 4 | D13: 2.53 | E13: 3 | F13: 0.1 | G13: 3 | H13: 0.09 | I13: 4 | J13: 3 | K13: 0.12 | L13: 3 | M13: 0.1
A14: 4q99346 | B14: 7 | C14: 4 | D14: 8.08 | E14: 3 | F14: 0.11 | G14: 3 | H14: 0.44 | I14: 6 | J14: 3 | K14: 0.21 | L14: 3 | M14: 0.36
A15: 5q05306 | B15: 10 | C15: 8 | D15: 437.1 | E15: 5 | F15: 1.64 | G15: 5 | H15: 9.68 | I15: 8 | J15: 4 | K15: 2.57 | L15: 4 | M15: 4.56
A16: 5q33936 | B16: 10 | C16: 7 | D16: 533.8 | E16: 5 | F16: 0.91 | G16: 5 | H16: 6.3 | I16: 8 | J16: 4 | K16: 2.81 | L16: 4 | M16: 7
... A19: 5q99346 | B19: 9 | C19: 6 | D19: 226.7 | E19: 4 | F19: 0.39 | G19: 4 | H19: 3.25 | I19: 8 | J19: 4 | K19: 0.37 | L19: 4 | M19: 5.41
A20: 6q05306 | B20: 11 | C20: - | D20: TO | E20: 5 | F20: 23.59 | G20: 5 | H20: 299.27 | I20: 11 | J20: 5 | K20: 168.09 | L20: 5 | M20: 607.01
A21: 6q33936 | B21: 16 | C21: 11 | D21: TO | E21: 5 | F21: 6.39 | G21: 5 | H21: 994.98 | I21: 10 | J21: 5 | K21: 60.75 | L21: 5 | M21: 379.15
A22: 6q50494 | B22: 14 | C22: 14 | D22: TO | E22: 5 | F22: 1.86 | G22: 5 | H22: 741.38 | I22: 11 | J22: 5 | K22: 64.86 | L22: 5 | M22: 357.08
A23: 6q55125 | B23: 15 | C23: 17 | D23: TO | E23: 5 | F23: 3.03 | G23: 5 | H23: 638.7 | I23: 12 | J23: 5 | K23: 35.44 | L23: 5 | M23: 587.76
A24: 6q99346 | B24: 12 | C24: 11 | D24: TO | E24: 5 | F24: 17.66 | G24: 5 | H24: 1522.43 | I24: 12 | J24: 5 | K24: 82.35 | L24: 5 | M24: 984.03
A25: 7q05306 | B25: 19 | C25: - | D25: TO | E25: - | F25: TO | G25: 18 | H25: TO | I25: 18 | J25: - | K25: TO | L25: - | M25: TO
A26: 7q33936 | B26: 19 | C26: - | D26: TO | E26: 6 | F26: 4151.7 | G26: - | H26: TO | I26: 16 | J26: - | K26: TO | L26: - | M26: TO
A27: 7q50494 | B27: 18 | C27: - | D27: TO | E27: 6 | F27: 7347 | G27: - | H27: TO | I27: 15 | J27: - | K27: TO | L27: - | M27: TO
A28: 7q55125 | B28: 19 | C28: - | D28: TO | E28: 6 | F28: 1485.5 | G28: - | H28: TO | I28: 14 | J28: - | K28: TO | L28: 12 | M28: TO
A29: 7q99346 | B29: 15 | C29: - | D29: TO | E29: 6 | F29: 241 | G29: - | H29: TO | I29: 14 | J29: - | K29: TO | L29: - | M29: TO

Sheet summ
A2: file: SATCircuits/Random-Clifford/
A3: method:
D5: 1 | E5: 1a | F5: 2 | G5: 3 | H5: 4 | I5: 4a | J5: 5 | K5: 6 | L5: 7 | M5: 7a | N5: 8 | O5: 9 | P5: 10
C7: n | D7: Match | R7: GateCount | AF7: Time
A8: Circuit | D8: {=SUBSTITUTE(INDIRECT("Sheet"&D$5&"!a1"),$A$2,"")} -> tket_optimized_0cost_swaps | E8: {=SUBSTITUTE(INDIRECT("Sheet"&E$5&"!a1"),$A$2,"")} -> tket_optimized_0cost_swaps | F8: {=SUBSTITUTE(INDIRECT("Sheet"&F$5&"!a1"),$A$2,"")} -> tket_optimized_0cost_swaps | G8: {=SUBSTITUTE(INDIRECT("Sheet"&G$5&"!a1"),$A$2,"")} -> tket_optimized_0cost_swaps | H8: {=SUBSTITUTE(INDIRECT("Sheet"&H$5&"!a1"),$A$2,"")} -> tket_optimized_without_swaps_no_u3_gates | I8: {=SUBSTITUTE(INDIRECT("Sheet"&I$5&"!a1"),$A$2,"")} -> tket_optimized_without_swaps_gates | J8: {=SUBSTITUTE(INDIRECT("Sheet"&J$5&"!a1"),$A$2,"")} -> tket_optimized_without_swaps_gates | K8: {=SUBSTITUTE(INDIRECT("Sheet"&K$5&"!a1"),$A$2,"")} -> tket_optimized_without_swaps_gates | ... P8: {=SUBSTITUTE(INDIRECT("Sheet"&P$5&"!a1"),$A$2,"")} -> qsynth_0cost_swaps
A9: Method | D9: {=SUBSTITUTE(INDIRECT("Sheet"&D$5&"!a2"),$A$3,"")} -> astar | E9: {=SUBSTITUTE(INDIRECT("Sheet"&E$5&"!a2"),$A$3,"")} -> astar | F9: {=SUBSTITUTE(INDIRECT("Sheet"&F$5&"!a2"),$A$3,"")} -> greedy | G9: {=SUBSTITUTE(INDIRECT("Sheet"&G$5&"!a2"),$A$3,"")} -> qiskit | H9: {=SUBSTITUTE(INDIRECT("Sheet"&H$5&"!a2"),$A$3,"")} -> astar | I9: {=SUBSTITUTE(INDIRECT("Sheet"&I$5&"!a2"),$A$3,"")} -> astar | J9: {=SUBSTITUTE(INDIRECT("Sheet"&J$5&"!a2"),$A$3,"")} -> greedy | K9: {=SUBSTITUTE(INDIRECT("Sheet"&K$5&"!a2"),$A$3,"")} -> qiskit | ... P9: {=SUBSTITUTE(INDIRECT("Sheet"&P$5&"!a2"),$A$3,"")} -> optimal | R9: =D9 -> astar | S9: =E9 -> astar | T9: =F9 -> greedy | U9: =G9 -> qiskit | V9: =H9 -> astar | W9: =I9 -> astar | X9: =J9 -> greedy | Y9: =K9 -> qiskit | ... AD9: =P9 -> optimal | AF9: =R9 -> astar | AG9: =S9 -> astar | AH9: =T9 -> greedy | AI9: =U9 -> qiskit | AJ9: =V9 -> astar | AK9: =W9 -> astar | AL9: =X9 -> greedy | AM9: =Y9 -> qiskit | ... AR9: =AD9 -> optimal
A10: Count | D10: =COUNT(INDIRECT("Sheet"&D$5&"!c:c")) -> 25 | E10: =COUNT(INDIRECT("Sheet"&E$5&"!c:c")) -> 25 | F10: =COUNT(INDIRECT("Sheet"&F$5&"!c:c")) -> 25 | G10: =COUNT(INDIRECT("Sheet"&G$5&"!c:c")) -> 25 | H10: =COUNT(INDIRECT("Sheet"&H$5&"!c:c")) -> 25 | I10: =COUNT(INDIRECT("Sheet"&I$5&"!c:c")) -> 0 | J10: =COUNT(INDIRECT("Sheet"&J$5&"!c:c")) -> 0 | K10: =COUNT(INDIRECT("Sheet"&K$5&"!c:c")) -> 0 | ... P10: =COUNT(INDIRECT("Sheet"&P$5&"!c:c")) -> 25
A11: 1 | B11: 03q_05306.qasm | C11: 3 | D11: =MATCH($A11,INDIRECT("Sheet"&D$5&"!a:a"),) -> 19 | E11: =MATCH($A11,INDIRECT("Sheet"&E$5&"!a:a"),) -> 19 | F11: =MATCH($A11,INDIRECT("Sheet"&F$5&"!a:a"),) -> 19 | G11: =MATCH($A11,INDIRECT("Sheet"&G$5&"!a:a"),) -> 19 | H11: =MATCH($A11,INDIRECT("Sheet"&H$5&"!a:a"),) -> 19 | I11: =MATCH($A11,INDIRECT("Sheet"&I$5&"!a:a"),) -> #N/A | J11: =MATCH($A11,INDIRECT("Sheet"&J$5&"!a:a"),) -> #N/A | K11: =MATCH($A11,INDIRECT("Sheet"&K$5&"!a:a"),) -> #N/A | ... P11: =MATCH($A11,INDIRECT("Sheet"&P$5&"!a:a"),) -> 19 | R11: {=OFFSET(INDIRECT("Sheet"&D$5&"!d1"),D11-1,)} -> 2 | S11: {=OFFSET(INDIRECT("Sheet"&E$5&"!d1"),E11-1,)} -> 2 | T11: {=OFFSET(INDIRECT("Sheet"&F$5&"!d1"),F11-1,)} -> 2 | U11: {=OFFSET(INDIRECT("Sheet"&G$5&"!d1"),G11-1,)} -> 5 | V11: {=OFFSET(INDIRECT("Sheet"&H$5&"!d1"),H11-1,)} -> 2 | W11: {=OFFSET(INDIRECT("Sheet"&I$5&"!d1"),I11-1,)} -> #N/A | X11: {=OFFSET(INDIRECT("Sheet"&J$5&"!d1"),J11-1,)} -> #N/A | Y11: {=OFFSET(INDIRECT("Sheet"&K$5&"!d1"),K11-1,)} -> #N/A | ... AD11: {=OFFSET(INDIRECT("Sheet"&P$5&"!d1"),P11-1,)} -> 2 | AF11: {=OFFSET(INDIRECT("Sheet"&D$5&"!f1"),D11-1,)} -> 0.36817837 | AG11: {=OFFSET(INDIRECT("Sheet"&E$5&"!f1"),E11-1,)} -> 0.26445427 | AH11: {=OFFSET(INDIRECT("Sheet"&F$5&"!f1"),F11-1,)} -> 0.30444326 | AI11: {=OFFSET(INDIRECT("Sheet"&G$5&"!f1"),G11-1,)} -> 0.0022555813 | AJ11: {=OFFSET(INDIRECT("Sheet"&H$5&"!f1"),H11-1,)} -> 0.36734439 | AK11: {=OFFSET(INDIRECT("Sheet"&I$5&"!f1"),I11-1,)} -> #N/A | AL11: {=OFFSET(INDIRECT("Sheet"&J$5&"!f1"),J11-1,)} -> #N/A | AM11: {=OFFSET(INDIRECT("Sheet"&K$5&"!f1"),K11-1,)} -> #N/A | ... AR11: {=OFFSET(INDIRECT("Sheet"&P$5&"!f1"),P11-1,)} -> 0.010961708
A12: 2 | B12: 03q_33936.qasm | C12: 3 | D12: =MATCH($A12,INDIRECT("Sheet"&D$5&"!a:a"),) -> 20 | E12: =MATCH($A12,INDIRECT("Sheet"&E$5&"!a:a"),) -> 20 | F12: =MATCH($A12,INDIRECT("Sheet"&F$5&"!a:a"),) -> 20 | G12: =MATCH($A12,INDIRECT("Sheet"&G$5&"!a:a"),) -> 20 | H12: =MATCH($A12,INDIRECT("Sheet"&H$5&"!a:a"),) -> 20 | I12: =MATCH($A12,INDIRECT("Sheet"&I$5&"!a:a"),) -> #N/A | J12: =MATCH($A12,INDIRECT("Sheet"&J$5&"!a:a"),) -> #N/A | K12: =MATCH($A12,INDIRECT("Sheet"&K$5&"!a:a"),) -> #N/A | ... P12: =MATCH($A12,INDIRECT("Sheet"&P$5&"!a:a"),) -> 20 | R12: {=OFFSET(INDIRECT("Sheet"&D$5&"!d1"),D12-1,)} -> 3 | S12: {=OFFSET(INDIRECT("Sheet"&E$5&"!d1"),E12-1,)} -> 3 | T12: {=OFFSET(INDIRECT("Sheet"&F$5&"!d1"),F12-1,)} -> 3 | U12: {=OFFSET(INDIRECT("Sheet"&G$5&"!d1"),G12-1,)} -> 5 | V12: {=OFFSET(INDIRECT("Sheet"&H$5&"!d1"),H12-1,)} -> 3 | W12: {=OFFSET(INDIRECT("Sheet"&I$5&"!d1"),I12-1,)} -> #N/A | X12: {=OFFSET(INDIRECT("Sheet"&J$5&"!d1"),J12-1,)} -> #N/A | Y12: {=OFFSET(INDIRECT("Sheet"&K$5&"!d1"),K12-1,)} -> #N/A | ... AD12: {=OFFSET(INDIRECT("Sheet"&P$5&"!d1"),P12-1,)} -> 3 | AF12: {=OFFSET(INDIRECT("Sheet"&D$5&"!f1"),D12-1,)} -> 0.00496018 | AG12: {=OFFSET(INDIRECT("Sheet"&E$5&"!f1"),E12-1,)} -> 0.005208969 | AH12: {=OFFSET(INDIRECT("Sheet"&F$5&"!f1"),F12-1,)} -> 0.006433622 | AI12: {=OFFSET(INDIRECT("Sheet"&G$5&"!f1"),G12-1,)} -> 0.0019067824 | AJ12: {=OFFSET(INDIRECT("Sheet"&H$5&"!f1"),H12-1,)} -> 0.004915971 | AK12: {=OFFSET(INDIRECT("Sheet"&I$5&"!f1"),I12-1,)} -> #N/A | AL12: {=OFFSET(INDIRECT("Sheet"&J$5&"!f1"),J12-1,)} -> #N/A | AM12: {=OFFSET(INDIRECT("Sheet"&K$5&"!f1"),K12-1,)} -> #N/A | ... AR12: {=OFFSET(INDIRECT("Sheet"&P$5&"!f1"),P12-1,)} -> 0.001359125
A13: 3 | B13: 03q_50494.qasm | C13: 3 | D13: =MATCH($A13,INDIRECT("Sheet"&D$5&"!a:a"),) -> 21 | E13: =MATCH($A13,INDIRECT("Sheet"&E$5&"!a:a"),) -> 21 | F13: =MATCH($A13,INDIRECT("Sheet"&F$5&"!a:a"),) -> 21 | G13: =MATCH($A13,INDIRECT("Sheet"&G$5&"!a:a"),) -> 21 | H13: =MATCH($A13,INDIRECT("Sheet"&H$5&"!a:a"),) -> 21 | I13: =MATCH($A13,INDIRECT("Sheet"&I$5&"!a:a"),) -> #N/A | J13: =MATCH($A13,INDIRECT("Sheet"&J$5&"!a:a"),) -> #N/A | K13: =MATCH($A13,INDIRECT("Sheet"&K$5&"!a:a"),) -> #N/A | ... P13: =MATCH($A13,INDIRECT("Sheet"&P$5&"!a:a"),) -> 21 | R13: {=OFFSET(INDIRECT("Sheet"&D$5&"!d1"),D13-1,)} -> 3 | S13: {=OFFSET(INDIRECT("Sheet"&E$5&"!d1"),E13-1,)} -> 3 | T13: {=OFFSET(INDIRECT("Sheet"&F$5&"!d1"),F13-1,)} -> 3 | U13: {=OFFSET(INDIRECT("Sheet"&G$5&"!d1"),G13-1,)} -> 8 | V13: {=OFFSET(INDIRECT("Sheet"&H$5&"!d1"),H13-1,)} -> 3 | W13: {=OFFSET(INDIRECT("Sheet"&I$5&"!d1"),I13-1,)} -> #N/A | X13: {=OFFSET(INDIRECT("Sheet"&J$5&"!d1"),J13-1,)} -> #N/A | Y13: {=OFFSET(INDIRECT("Sheet"&K$5&"!d1"),K13-1,)} -> #N/A | ... AD13: {=OFFSET(INDIRECT("Sheet"&P$5&"!d1"),P13-1,)} -> 3 | AF13: {=OFFSET(INDIRECT("Sheet"&D$5&"!f1"),D13-1,)} -> 0.004834851 | AG13: {=OFFSET(INDIRECT("Sheet"&E$5&"!f1"),E13-1,)} -> 0.00497927 | AH13: {=OFFSET(INDIRECT("Sheet"&F$5&"!f1"),F13-1,)} -> 0.006156026 | AI13: {=OFFSET(INDIRECT("Sheet"&G$5&"!f1"),G13-1,)} -> 0.0010847449 | AJ13: {=OFFSET(INDIRECT("Sheet"&H$5&"!f1"),H13-1,)} -> 0.004817453 | AK13: {=OFFSET(INDIRECT("Sheet"&I$5&"!f1"),I13-1,)} -> #N/A | AL13: {=OFFSET(INDIRECT("Sheet"&J$5&"!f1"),J13-1,)} -> #N/A | AM13: {=OFFSET(INDIRECT("Sheet"&K$5&"!f1"),K13-1,)} -> #N/A | ... AR13: {=OFFSET(INDIRECT("Sheet"&P$5&"!f1"),P13-1,)} -> 0.001352333
A14: 4 | B14: 03q_55125.qasm | C14: 3 | D14: =MATCH($A14,INDIRECT("Sheet"&D$5&"!a:a"),) -> 22 | E14: =MATCH($A14,INDIRECT("Sheet"&E$5&"!a:a"),) -> 22 | F14: =MATCH($A14,INDIRECT("Sheet"&F$5&"!a:a"),) -> 22 | G14: =MATCH($A14,INDIRECT("Sheet"&G$5&"!a:a"),) -> 22 | H14: =MATCH($A14,INDIRECT("Sheet"&H$5&"!a:a"),) -> 22 | I14: =MATCH($A14,INDIRECT("Sheet"&I$5&"!a:a"),) -> #N/A | J14: =MATCH($A14,INDIRECT("Sheet"&J$5&"!a:a"),) -> #N/A | K14: =MATCH($A14,INDIRECT("Sheet"&K$5&"!a:a"),) -> #N/A | ... P14: =MATCH($A14,INDIRECT("Sheet"&P$5&"!a:a"),) -> 22 | R14: {=OFFSET(INDIRECT("Sheet"&D$5&"!d1"),D14-1,)} -> 3 | S14: {=OFFSET(INDIRECT("Sheet"&E$5&"!d1"),E14-1,)} -> 3 | T14: {=OFFSET(INDIRECT("Sheet"&F$5&"!d1"),F14-1,)} -> 3 | U14: {=OFFSET(INDIRECT("Sheet"&G$5&"!d1"),G14-1,)} -> 7 | V14: {=OFFSET(INDIRECT("Sheet"&H$5&"!d1"),H14-1,)} -> 3 | W14: {=OFFSET(INDIRECT("Sheet"&I$5&"!d1"),I14-1,)} -> #N/A | X14: {=OFFSET(INDIRECT("Sheet"&J$5&"!d1"),J14-1,)} -> #N/A | Y14: {=OFFSET(INDIRECT("Sheet"&K$5&"!d1"),K14-1,)} -> #N/A | ... AD14: {=OFFSET(INDIRECT("Sheet"&P$5&"!d1"),P14-1,)} -> 3 | AF14: {=OFFSET(INDIRECT("Sheet"&D$5&"!f1"),D14-1,)} -> 0.004870141 | AG14: {=OFFSET(INDIRECT("Sheet"&E$5&"!f1"),E14-1,)} -> 0.005353959 | AH14: {=OFFSET(INDIRECT("Sheet"&F$5&"!f1"),F14-1,)} -> 0.006390825 | AI14: {=OFFSET(INDIRECT("Sheet"&G$5&"!f1"),G14-1,)} -> 0.0010203123 | AJ14: {=OFFSET(INDIRECT("Sheet"&H$5&"!f1"),H14-1,)} -> 0.004852717 | AK14: {=OFFSET(INDIRECT("Sheet"&I$5&"!f1"),I14-1,)} -> #N/A | AL14: {=OFFSET(INDIRECT("Sheet"&J$5&"!f1"),J14-1,)} -> #N/A | AM14: {=OFFSET(INDIRECT("Sheet"&K$5&"!f1"),K14-1,)} -> #N/A | ... AR14: {=OFFSET(INDIRECT("Sheet"&P$5&"!f1"),P14-1,)} -> 0.001281958
A15: 5 | B15: 03q_99346.qasm | C15: 3 | D15: =MATCH($A15,INDIRECT("Sheet"&D$5&"!a:a"),) -> 23 | E15: =MATCH($A15,INDIRECT("Sheet"&E$5&"!a:a"),) -> 23 | F15: =MATCH($A15,INDIRECT("Sheet"&F$5&"!a:a"),) -> 23 | G15: =MATCH($A15,INDIRECT("Sheet"&G$5&"!a:a"),) -> 23 | H15: =MATCH($A15,INDIRECT("Sheet"&H$5&"!a:a"),) -> 23 | I15: =MATCH($A15,INDIRECT("Sheet"&I$5&"!a:a"),) -> #N/A | J15: =MATCH($A15,INDIRECT("Sheet"&J$5&"!a:a"),) -> #N/A | K15: =MATCH($A15,INDIRECT("Sheet"&K$5&"!a:a"),) -> #N/A | ... P15: =MATCH($A15,INDIRECT("Sheet"&P$5&"!a:a"),) -> 23 | R15: {=OFFSET(INDIRECT("Sheet"&D$5&"!d1"),D15-1,)} -> 3 | S15: {=OFFSET(INDIRECT("Sheet"&E$5&"!d1"),E15-1,)} -> 3 | T15: {=OFFSET(INDIRECT("Sheet"&F$5&"!d1"),F15-1,)} -> 3 | U15: {=OFFSET(INDIRECT("Sheet"&G$5&"!d1"),G15-1,)} -> 7 | V15: {=OFFSET(INDIRECT("Sheet"&H$5&"!d1"),H15-1,)} -> 3 | W15: {=OFFSET(INDIRECT("Sheet"&I$5&"!d1"),I15-1,)} -> #N/A | X15: {=OFFSET(INDIRECT("Sheet"&J$5&"!d1"),J15-1,)} -> #N/A | Y15: {=OFFSET(INDIRECT("Sheet"&K$5&"!d1"),K15-1,)} -> #N/A | ... AD15: {=OFFSET(INDIRECT("Sheet"&P$5&"!d1"),P15-1,)} -> 3 | AF15: {=OFFSET(INDIRECT("Sheet"&D$5&"!f1"),D15-1,)} -> 0.004942298 | AG15: {=OFFSET(INDIRECT("Sheet"&E$5&"!f1"),E15-1,)} -> 0.004966357 | AH15: {=OFFSET(INDIRECT("Sheet"&F$5&"!f1"),F15-1,)} -> 0.006314003 | AI15: {=OFFSET(INDIRECT("Sheet"&G$5&"!f1"),G15-1,)} -> 0.00092547387 | AJ15: {=OFFSET(INDIRECT("Sheet"&H$5&"!f1"),H15-1,)} -> 0.004901861 | AK15: {=OFFSET(INDIRECT("Sheet"&I$5&"!f1"),I15-1,)} -> #N/A | AL15: {=OFFSET(INDIRECT("Sheet"&J$5&"!f1"),J15-1,)} -> #N/A | AM15: {=OFFSET(INDIRECT("Sheet"&K$5&"!f1"),K15-1,)} -> #N/A | ... AR15: {=OFFSET(INDIRECT("Sheet"&P$5&"!f1"),P15-1,)} -> 0.001065917
A16: 6 | B16: 04q_05306.qasm | C16: 4 | D16: =MATCH($A16,INDIRECT("Sheet"&D$5&"!a:a"),) -> 24 | E16: =MATCH($A16,INDIRECT("Sheet"&E$5&"!a:a"),) -> 24 | F16: =MATCH($A16,INDIRECT("Sheet"&F$5&"!a:a"),) -> 24 | G16: =MATCH($A16,INDIRECT("Sheet"&G$5&"!a:a"),) -> 24 | H16: =MATCH($A16,INDIRECT("Sheet"&H$5&"!a:a"),) -> 24 | I16: =MATCH($A16,INDIRECT("Sheet"&I$5&"!a:a"),) -> #N/A | J16: =MATCH($A16,INDIRECT("Sheet"&J$5&"!a:a"),) -> #N/A | K16: =MATCH($A16,INDIRECT("Sheet"&K$5&"!a:a"),) -> #N/A | ... P16: =MATCH($A16,INDIRECT("Sheet"&P$5&"!a:a"),) -> 24 | R16: {=OFFSET(INDIRECT("Sheet"&D$5&"!d1"),D16-1,)} -> 5 | S16: {=OFFSET(INDIRECT("Sheet"&E$5&"!d1"),E16-1,)} -> 5 | T16: {=OFFSET(INDIRECT("Sheet"&F$5&"!d1"),F16-1,)} -> 5 | U16: {=OFFSET(INDIRECT("Sheet"&G$5&"!d1"),G16-1,)} -> 11 | V16: {=OFFSET(INDIRECT("Sheet"&H$5&"!d1"),H16-1,)} -> 5 | W16: {=OFFSET(INDIRECT("Sheet"&I$5&"!d1"),I16-1,)} -> #N/A | X16: {=OFFSET(INDIRECT("Sheet"&J$5&"!d1"),J16-1,)} -> #N/A | Y16: {=OFFSET(INDIRECT("Sheet"&K$5&"!d1"),K16-1,)} -> #N/A | ... AD16: {=OFFSET(INDIRECT("Sheet"&P$5&"!d1"),P16-1,)} -> 5 | AF16: {=OFFSET(INDIRECT("Sheet"&D$5&"!f1"),D16-1,)} -> 0.20923711 | AG16: {=OFFSET(INDIRECT("Sheet"&E$5&"!f1"),E16-1,)} -> 0.22933948 | AH16: {=OFFSET(INDIRECT("Sheet"&F$5&"!f1"),F16-1,)} -> 0.019167533 | AI16: {=OFFSET(INDIRECT("Sheet"&G$5&"!f1"),G16-1,)} -> 0.0011087954 | AJ16: {=OFFSET(INDIRECT("Sheet"&H$5&"!f1"),H16-1,)} -> 0.2079283 | AK16: {=OFFSET(INDIRECT("Sheet"&I$5&"!f1"),I16-1,)} -> #N/A | AL16: {=OFFSET(INDIRECT("Sheet"&J$5&"!f1"),J16-1,)} -> #N/A | AM16: {=OFFSET(INDIRECT("Sheet"&K$5&"!f1"),K16-1,)} -> #N/A | ... AR16: {=OFFSET(INDIRECT("Sheet"&P$5&"!f1"),P16-1,)} -> 0.002832666
A17: 7 | B17: 04q_33936.qasm | C17: 4 | D17: =MATCH($A17,INDIRECT("Sheet"&D$5&"!a:a"),) -> 25 | E17: =MATCH($A17,INDIRECT("Sheet"&E$5&"!a:a"),) -> 25 | F17: =MATCH($A17,INDIRECT("Sheet"&F$5&"!a:a"),) -> 25 | G17: =MATCH($A17,INDIRECT("Sheet"&G$5&"!a:a"),) -> 25 | H17: =MATCH($A17,INDIRECT("Sheet"&H$5&"!a:a"),) -> 25 | I17: =MATCH($A17,INDIRECT("Sheet"&I$5&"!a:a"),) -> #N/A | J17: =MATCH($A17,INDIRECT("Sheet"&J$5&"!a:a"),) -> #N/A | K17: =MATCH($A17,INDIRECT("Sheet"&K$5&"!a:a"),) -> #N/A | ... P17: =MATCH($A17,INDIRECT("Sheet"&P$5&"!a:a"),) -> 25 | R17: {=OFFSET(INDIRECT("Sheet"&D$5&"!d1"),D17-1,)} -> 5 | S17: {=OFFSET(INDIRECT("Sheet"&E$5&"!d1"),E17-1,)} -> 5 | T17: {=OFFSET(INDIRECT("Sheet"&F$5&"!d1"),F17-1,)} -> 5 | U17: {=OFFSET(INDIRECT("Sheet"&G$5&"!d1"),G17-1,)} -> 11 | V17: {=OFFSET(INDIRECT("Sheet"&H$5&"!d1"),H17-1,)} -> 5 | W17: {=OFFSET(INDIRECT("Sheet"&I$5&"!d1"),I17-1,)} -> #N/A | X17: {=OFFSET(INDIRECT("Sheet"&J$5&"!d1"),J17-1,)} -> #N/A | Y17: {=OFFSET(INDIRECT("Sheet"&K$5&"!d1"),K17-1,)} -> #N/A | ... AD17: {=OFFSET(INDIRECT("Sheet"&P$5&"!d1"),P17-1,)} -> 5 | AF17: {=OFFSET(INDIRECT("Sheet"&D$5&"!f1"),D17-1,)} -> 0.20583972 | AG17: {=OFFSET(INDIRECT("Sheet"&E$5&"!f1"),E17-1,)} -> 0.21881667 | AH17: {=OFFSET(INDIRECT("Sheet"&F$5&"!f1"),F17-1,)} -> 0.016144929 | AI17: {=OFFSET(INDIRECT("Sheet"&G$5&"!f1"),G17-1,)} -> 0.0011905283 | AJ17: {=OFFSET(INDIRECT("Sheet"&H$5&"!f1"),H17-1,)} -> 0.20419291 | AK17: {=OFFSET(INDIRECT("Sheet"&I$5&"!f1"),I17-1,)} -> #N/A | AL17: {=OFFSET(INDIRECT("Sheet"&J$5&"!f1"),J17-1,)} -> #N/A | AM17: {=OFFSET(INDIRECT("Sheet"&K$5&"!f1"),K17-1,)} -> #N/A | ... AR17: {=OFFSET(INDIRECT("Sheet"&P$5&"!f1"),P17-1,)} -> 0.001150459
A18: 8 | B18: 04q_50494.qasm | C18: 4 | D18: =MATCH($A18,INDIRECT("Sheet"&D$5&"!a:a"),) -> 26 | E18: =MATCH($A18,INDIRECT("Sheet"&E$5&"!a:a"),) -> 26 | F18: =MATCH($A18,INDIRECT("Sheet"&F$5&"!a:a"),) -> 26 | G18: =MATCH($A18,INDIRECT("Sheet"&G$5&"!a:a"),) -> 26 | H18: =MATCH($A18,INDIRECT("Sheet"&H$5&"!a:a"),) -> 26 | I18: =MATCH($A18,INDIRECT("Sheet"&I$5&"!a:a"),) -> #N/A | J18: =MATCH($A18,INDIRECT("Sheet"&J$5&"!a:a"),) -> #N/A | K18: =MATCH($A18,INDIRECT("Sheet"&K$5&"!a:a"),) -> #N/A | ... P18: =MATCH($A18,INDIRECT("Sheet"&P$5&"!a:a"),) -> 26 | R18: {=OFFSET(INDIRECT("Sheet"&D$5&"!d1"),D18-1,)} -> 4 | S18: {=OFFSET(INDIRECT("Sheet"&E$5&"!d1"),E18-1,)} -> 4 | T18: {=OFFSET(INDIRECT("Sheet"&F$5&"!d1"),F18-1,)} -> 4 | U18: {=OFFSET(INDIRECT("Sheet"&G$5&"!d1"),G18-1,)} -> 7 | V18: {=OFFSET(INDIRECT("Sheet"&H$5&"!d1"),H18-1,)} -> 4 | W18: {=OFFSET(INDIRECT("Sheet"&I$5&"!d1"),I18-1,)} -> #N/A | X18: {=OFFSET(INDIRECT("Sheet"&J$5&"!d1"),J18-1,)} -> #N/A | Y18: {=OFFSET(INDIRECT("Sheet"&K$5&"!d1"),K18-1,)} -> #N/A | ... AD18: {=OFFSET(INDIRECT("Sheet"&P$5&"!d1"),P18-1,)} -> 4 | AF18: {=OFFSET(INDIRECT("Sheet"&D$5&"!f1"),D18-1,)} -> 0.008700126 | AG18: {=OFFSET(INDIRECT("Sheet"&E$5&"!f1"),E18-1,)} -> 0.009019647 | AH18: {=OFFSET(INDIRECT("Sheet"&F$5&"!f1"),F18-1,)} -> 0.010180927 | AI18: {=OFFSET(INDIRECT("Sheet"&G$5&"!f1"),G18-1,)} -> 0.001270771 | AJ18: {=OFFSET(INDIRECT("Sheet"&H$5&"!f1"),H18-1,)} -> 0.008660629 | AK18: {=OFFSET(INDIRECT("Sheet"&I$5&"!f1"),I18-1,)} -> #N/A | AL18: {=OFFSET(INDIRECT("Sheet"&J$5&"!f1"),J18-1,)} -> #N/A | AM18: {=OFFSET(INDIRECT("Sheet"&K$5&"!f1"),K18-1,)} -> #N/A | ... AR18: {=OFFSET(INDIRECT("Sheet"&P$5&"!f1"),P18-1,)} -> 0.001172459
A19: 9 | B19: 04q_55125.qasm | C19: 4 | D19: =MATCH($A19,INDIRECT("Sheet"&D$5&"!a:a"),) -> 27 | E19: =MATCH($A19,INDIRECT("Sheet"&E$5&"!a:a"),) -> 27 | F19: =MATCH($A19,INDIRECT("Sheet"&F$5&"!a:a"),) -> 27 | G19: =MATCH($A19,INDIRECT("Sheet"&G$5&"!a:a"),) -> 27 | H19: =MATCH($A19,INDIRECT("Sheet"&H$5&"!a:a"),) -> 27 | I19: =MATCH($A19,INDIRECT("Sheet"&I$5&"!a:a"),) -> #N/A | J19: =MATCH($A19,INDIRECT("Sheet"&J$5&"!a:a"),) -> #N/A | K19: =MATCH($A19,INDIRECT("Sheet"&K$5&"!a:a"),) -> #N/A | ... P19: =MATCH($A19,INDIRECT("Sheet"&P$5&"!a:a"),) -> 27 | R19: {=OFFSET(INDIRECT("Sheet"&D$5&"!d1"),D19-1,)} -> 5 | S19: {=OFFSET(INDIRECT("Sheet"&E$5&"!d1"),E19-1,)} -> 5 | T19: {=OFFSET(INDIRECT("Sheet"&F$5&"!d1"),F19-1,)} -> 6 | U19: {=OFFSET(INDIRECT("Sheet"&G$5&"!d1"),G19-1,)} -> 13 | V19: {=OFFSET(INDIRECT("Sheet"&H$5&"!d1"),H19-1,)} -> 5 | W19: {=OFFSET(INDIRECT("Sheet"&I$5&"!d1"),I19-1,)} -> #N/A | X19: {=OFFSET(INDIRECT("Sheet"&J$5&"!d1"),J19-1,)} -> #N/A | Y19: {=OFFSET(INDIRECT("Sheet"&K$5&"!d1"),K19-1,)} -> #N/A | ... AD19: {=OFFSET(INDIRECT("Sheet"&P$5&"!d1"),P19-1,)} -> 5 | AF19: {=OFFSET(INDIRECT("Sheet"&D$5&"!f1"),D19-1,)} -> 0.20000194 | AG19: {=OFFSET(INDIRECT("Sheet"&E$5&"!f1"),E19-1,)} -> 0.21512024 | AH19: {=OFFSET(INDIRECT("Sheet"&F$5&"!f1"),F19-1,)} -> 0.019910293 | AI19: {=OFFSET(INDIRECT("Sheet"&G$5&"!f1"),G19-1,)} -> 0.0010872111 | AJ19: {=OFFSET(INDIRECT("Sheet"&H$5&"!f1"),H19-1,)} -> 0.19858226 | AK19: {=OFFSET(INDIRECT("Sheet"&I$5&"!f1"),I19-1,)} -> #N/A | AL19: {=OFFSET(INDIRECT("Sheet"&J$5&"!f1"),J19-1,)} -> #N/A | AM19: {=OFFSET(INDIRECT("Sheet"&K$5&"!f1"),K19-1,)} -> #N/A | ... AR19: {=OFFSET(INDIRECT("Sheet"&P$5&"!f1"),P19-1,)} -> 0.001124417
A20: 10 | B20: 04q_99346.qasm | C20: 4 | D20: =MATCH($A20,INDIRECT("Sheet"&D$5&"!a:a"),) -> 28 | E20: =MATCH($A20,INDIRECT("Sheet"&E$5&"!a:a"),) -> 28 | F20: =MATCH($A20,INDIRECT("Sheet"&F$5&"!a:a"),) -> 28 | G20: =MATCH($A20,INDIRECT("Sheet"&G$5&"!a:a"),) -> 28 | H20: =MATCH($A20,INDIRECT("Sheet"&H$5&"!a:a"),) -> 28 | I20: =MATCH($A20,INDIRECT("Sheet"&I$5&"!a:a"),) -> #N/A | J20: =MATCH($A20,INDIRECT("Sheet"&J$5&"!a:a"),) -> #N/A | K20: =MATCH($A20,INDIRECT("Sheet"&K$5&"!a:a"),) -> #N/A | ... P20: =MATCH($A20,INDIRECT("Sheet"&P$5&"!a:a"),) -> 28 | R20: {=OFFSET(INDIRECT("Sheet"&D$5&"!d1"),D20-1,)} -> 5 | S20: {=OFFSET(INDIRECT("Sheet"&E$5&"!d1"),E20-1,)} -> 5 | T20: {=OFFSET(INDIRECT("Sheet"&F$5&"!d1"),F20-1,)} -> 5 | U20: {=OFFSET(INDIRECT("Sheet"&G$5&"!d1"),G20-1,)} -> 8 | V20: {=OFFSET(INDIRECT("Sheet"&H$5&"!d1"),H20-1,)} -> 5 | W20: {=OFFSET(INDIRECT("Sheet"&I$5&"!d1"),I20-1,)} -> #N/A | X20: {=OFFSET(INDIRECT("Sheet"&J$5&"!d1"),J20-1,)} -> #N/A | Y20: {=OFFSET(INDIRECT("Sheet"&K$5&"!d1"),K20-1,)} -> #N/A | ... AD20: {=OFFSET(INDIRECT("Sheet"&P$5&"!d1"),P20-1,)} -> 5 | AF20: {=OFFSET(INDIRECT("Sheet"&D$5&"!f1"),D20-1,)} -> 0.21846146 | AG20: {=OFFSET(INDIRECT("Sheet"&E$5&"!f1"),E20-1,)} -> 0.23084293 | AH20: {=OFFSET(INDIRECT("Sheet"&F$5&"!f1"),F20-1,)} -> 0.016706432 | AI20: {=OFFSET(INDIRECT("Sheet"&G$5&"!f1"),G20-1,)} -> 0.0011371896 | AJ20: {=OFFSET(INDIRECT("Sheet"&H$5&"!f1"),H20-1,)} -> 0.21734399 | AK20: {=OFFSET(INDIRECT("Sheet"&I$5&"!f1"),I20-1,)} -> #N/A | AL20: {=OFFSET(INDIRECT("Sheet"&J$5&"!f1"),J20-1,)} -> #N/A | AM20: {=OFFSET(INDIRECT("Sheet"&K$5&"!f1"),K20-1,)} -> #N/A | ... AR20: {=OFFSET(INDIRECT("Sheet"&P$5&"!f1"),P20-1,)} -> 0.001200708
A21: 11 | B21: 05q_05306.qasm | C21: 5 | D21: =MATCH($A21,INDIRECT("Sheet"&D$5&"!a:a"),) -> 29 | E21: =MATCH($A21,INDIRECT("Sheet"&E$5&"!a:a"),) -> 29 | F21: =MATCH($A21,INDIRECT("Sheet"&F$5&"!a:a"),) -> 29 | G21: =MATCH($A21,INDIRECT("Sheet"&G$5&"!a:a"),) -> 29 | H21: =MATCH($A21,INDIRECT("Sheet"&H$5&"!a:a"),) -> 29 | I21: =MATCH($A21,INDIRECT("Sheet"&I$5&"!a:a"),) -> #N/A | J21: =MATCH($A21,INDIRECT("Sheet"&J$5&"!a:a"),) -> #N/A | K21: =MATCH($A21,INDIRECT("Sheet"&K$5&"!a:a"),) -> #N/A | ... P21: =MATCH($A21,INDIRECT("Sheet"&P$5&"!a:a"),) -> 29 | R21: {=OFFSET(INDIRECT("Sheet"&D$5&"!d1"),D21-1,)} -> 8 | S21: {=OFFSET(INDIRECT("Sheet"&E$5&"!d1"),E21-1,)} -> 8 | T21: {=OFFSET(INDIRECT("Sheet"&F$5&"!d1"),F21-1,)} -> 8 | U21: {=OFFSET(INDIRECT("Sheet"&G$5&"!d1"),G21-1,)} -> 17 | V21: {=OFFSET(INDIRECT("Sheet"&H$5&"!d1"),H21-1,)} -> 8 | W21: {=OFFSET(INDIRECT("Sheet"&I$5&"!d1"),I21-1,)} -> #N/A | X21: {=OFFSET(INDIRECT("Sheet"&J$5&"!d1"),J21-1,)} -> #N/A | Y21: {=OFFSET(INDIRECT("Sheet"&K$5&"!d1"),K21-1,)} -> #N/A | ... AD21: {=OFFSET(INDIRECT("Sheet"&P$5&"!d1"),P21-1,)} -> 8 | AF21: {=OFFSET(INDIRECT("Sheet"&D$5&"!f1"),D21-1,)} -> 2.7661903 | AG21: {=OFFSET(INDIRECT("Sheet"&E$5&"!f1"),E21-1,)} -> 20.645562 | AH21: {=OFFSET(INDIRECT("Sheet"&F$5&"!f1"),F21-1,)} -> 0.035736832 | AI21: {=OFFSET(INDIRECT("Sheet"&G$5&"!f1"),G21-1,)} -> 0.0018498003 | AJ21: {=OFFSET(INDIRECT("Sheet"&H$5&"!f1"),H21-1,)} -> 2.7433159 | AK21: {=OFFSET(INDIRECT("Sheet"&I$5&"!f1"),I21-1,)} -> #N/A | AL21: {=OFFSET(INDIRECT("Sheet"&J$5&"!f1"),J21-1,)} -> #N/A | AM21: {=OFFSET(INDIRECT("Sheet"&K$5&"!f1"),K21-1,)} -> #N/A | ... AR21: {=OFFSET(INDIRECT("Sheet"&P$5&"!f1"),P21-1,)} -> 0.004948292
A22: 12 | B22: 05q_33936.qasm | C22: 5 | D22: =MATCH($A22,INDIRECT("Sheet"&D$5&"!a:a"),) -> 30 | E22: =MATCH($A22,INDIRECT("Sheet"&E$5&"!a:a"),) -> 30 | F22: =MATCH($A22,INDIRECT("Sheet"&F$5&"!a:a"),) -> 30 | G22: =MATCH($A22,INDIRECT("Sheet"&G$5&"!a:a"),) -> 30 | H22: =MATCH($A22,INDIRECT("Sheet"&H$5&"!a:a"),) -> 30 | I22: =MATCH($A22,INDIRECT("Sheet"&I$5&"!a:a"),) -> #N/A | J22: =MATCH($A22,INDIRECT("Sheet"&J$5&"!a:a"),) -> #N/A | K22: =MATCH($A22,INDIRECT("Sheet"&K$5&"!a:a"),) -> #N/A | ... P22: =MATCH($A22,INDIRECT("Sheet"&P$5&"!a:a"),) -> 30 | R22: {=OFFSET(INDIRECT("Sheet"&D$5&"!d1"),D22-1,)} -> 8 | S22: {=OFFSET(INDIRECT("Sheet"&E$5&"!d1"),E22-1,)} -> 8 | T22: {=OFFSET(INDIRECT("Sheet"&F$5&"!d1"),F22-1,)} -> 9 | U22: {=OFFSET(INDIRECT("Sheet"&G$5&"!d1"),G22-1,)} -> 20 | V22: {=OFFSET(INDIRECT("Sheet"&H$5&"!d1"),H22-1,)} -> 8 | W22: {=OFFSET(INDIRECT("Sheet"&I$5&"!d1"),I22-1,)} -> #N/A | X22: {=OFFSET(INDIRECT("Sheet"&J$5&"!d1"),J22-1,)} -> #N/A | Y22: {=OFFSET(INDIRECT("Sheet"&K$5&"!d1"),K22-1,)} -> #N/A | ... AD22: {=OFFSET(INDIRECT("Sheet"&P$5&"!d1"),P22-1,)} -> 8 | AF22: {=OFFSET(INDIRECT("Sheet"&D$5&"!f1"),D22-1,)} -> 2.6938772 | AG22: {=OFFSET(INDIRECT("Sheet"&E$5&"!f1"),E22-1,)} -> 19.621635 | AH22: {=OFFSET(INDIRECT("Sheet"&F$5&"!f1"),F22-1,)} -> 0.046923149 | AI22: {=OFFSET(INDIRECT("Sheet"&G$5&"!f1"),G22-1,)} -> 0.0016954988 | AJ22: {=OFFSET(INDIRECT("Sheet"&H$5&"!f1"),H22-1,)} -> 2.697029 | AK22: {=OFFSET(INDIRECT("Sheet"&I$5&"!f1"),I22-1,)} -> #N/A | AL22: {=OFFSET(INDIRECT("Sheet"&J$5&"!f1"),J22-1,)} -> #N/A | AM22: {=OFFSET(INDIRECT("Sheet"&K$5&"!f1"),K22-1,)} -> #N/A | ... AR22: {=OFFSET(INDIRECT("Sheet"&P$5&"!f1"),P22-1,)} -> 0.003467667
... A35: 25 | B35: 07q_99346.qasm | C35: 7 | D35: =MATCH($A35,INDIRECT("Sheet"&D$5&"!a:a"),) -> 43 | E35: =MATCH($A35,INDIRECT("Sheet"&E$5&"!a:a"),) -> 43 | F35: =MATCH($A35,INDIRECT("Sheet"&F$5&"!a:a"),) -> 43 | G35: =MATCH($A35,INDIRECT("Sheet"&G$5&"!a:a"),) -> 43 | H35: =MATCH($A35,INDIRECT("Sheet"&H$5&"!a:a"),) -> 43 | I35: =MATCH($A35,INDIRECT("Sheet"&I$5&"!a:a"),) -> #N/A | J35: =MATCH($A35,INDIRECT("Sheet"&J$5&"!a:a"),) -> #N/A | K35: =MATCH($A35,INDIRECT("Sheet"&K$5&"!a:a"),) -> #N/A | ... P35: =MATCH($A35,INDIRECT("Sheet"&P$5&"!a:a"),) -> 43 | R35: {=OFFSET(INDIRECT("Sheet"&D$5&"!d1"),D35-1,)} -> 14 | S35: {=OFFSET(INDIRECT("Sheet"&E$5&"!d1"),E35-1,)} -> 14 | T35: {=OFFSET(INDIRECT("Sheet"&F$5&"!d1"),F35-1,)} -> 16 | U35: {=OFFSET(INDIRECT("Sheet"&G$5&"!d1"),G35-1,)} -> 40 | V35: {=OFFSET(INDIRECT("Sheet"&H$5&"!d1"),H35-1,)} -> 14 | W35: {=OFFSET(INDIRECT("Sheet"&I$5&"!d1"),I35-1,)} -> #N/A | X35: {=OFFSET(INDIRECT("Sheet"&J$5&"!d1"),J35-1,)} -> #N/A | Y35: {=OFFSET(INDIRECT("Sheet"&K$5&"!d1"),K35-1,)} -> #N/A | ... AD35: {=OFFSET(INDIRECT("Sheet"&P$5&"!d1"),P35-1,)} -> 0 | AF35: {=OFFSET(INDIRECT("Sheet"&D$5&"!f1"),D35-1,)} -> 12.46988 | AG35: {=OFFSET(INDIRECT("Sheet"&E$5&"!f1"),E35-1,)} -> 118.10673 | AH35: {=OFFSET(INDIRECT("Sheet"&F$5&"!f1"),F35-1,)} -> 0.14270985 | AI35: {=OFFSET(INDIRECT("Sheet"&G$5&"!f1"),G35-1,)} -> 0.0027687103 | AJ35: {=OFFSET(INDIRECT("Sheet"&H$5&"!f1"),H35-1,)} -> 12.412975 | AK35: {=OFFSET(INDIRECT("Sheet"&I$5&"!f1"),I35-1,)} -> #N/A | AL35: {=OFFSET(INDIRECT("Sheet"&J$5&"!f1"),J35-1,)} -> #N/A | AM35: {=OFFSET(INDIRECT("Sheet"&K$5&"!f1"),K35-1,)} -> #N/A | ... AR35: {=OFFSET(INDIRECT("Sheet"&P$5&"!f1"),P35-1,)} -> 0.000871708

Sheet Sheet1
A1: file: SATCircuits/Random-Clifford/tket_optimized_0cost_swaps
A2: method: astar
A3: submethod: 0
A4: mode: QC
A5: ixMin: 0
A6: ixMax: 0
A7: minDepth: 0
A8: wMax: 0
A9: hv: 1
A10: hr: 3
A11: hl: 1
A12: ht: 1
... A18: #########################################
A19: 1 | B19: 03q_05306.qasm | C19: 3 | D19: 2 | E19: 2 | F19: 0.36817837 | G19: TRUE | H19: QPerm:1,2,0 HS:0 HSH:1 S:2 tXZ:2,1 tXY:1,0
A20: 2 | B20: 03q_33936.qasm | C20: 3 | D20: 3 | E20: 3 | F20: 0.00496018 | G20: TRUE | H20: HSH:0 SH:2 tYX:0,2 tXY:2,1 tXZ:0,1
A21: 3 | B21: 03q_50494.qasm | C21: 3 | D21: 3 | E21: 3 | F21: 0.004834851 | G21: TRUE | H21: QPerm:1,2,0 S:0 HSH:1 HS:2 tYX:0,2 tXZ:2,1 tZX:0,1
A22: 4 | B22: 03q_55125.qasm | C22: 3 | D22: 3 | E22: 3 | F22: 0.004870141 | G22: TRUE | H22: QPerm:2,1,0 SH:0 S:1 HSH:2 tYY:0,1 tZY:2,1 tZX:0,2
A23: 5 | B23: 03q_99346.qasm | C23: 3 | D23: 3 | E23: 3 | F23: 0.004942298 | G23: TRUE | H23: QPerm:2,1,0 HSH:0 H:1 tZZ:2,0 tZZ:1,2 tXY:0,1
A24: 6 | B24: 04q_05306.qasm | C24: 4 | D24: 5 | E24: 5 | F24: 0.20923711 | G24: TRUE | H24: QPerm:0,1,3,2 SH:0 S:1 SH:2 tZY:1,2 tYX:3,2 tZZ:2,0 tXY:0,1 tZY:3,0
A25: 7 | B25: 04q_33936.qasm | C25: 4 | D25: 5 | E25: 5 | F25: 0.20583972 | G25: TRUE | H25: QPerm:3,1,0,2 HSH:0 H:1 HS:2 HSH:3 tZZ:1,3 tYX:3,2 tXX:0,3 tXZ:1,0 tYY:1,2
A26: 8 | B26: 04q_50494.qasm | C26: 4 | D26: 4 | E26: 4 | F26: 0.008700126 | G26: TRUE | H26: QPerm:1,3,0,2 HS:0 H:1 SH:2 HSH:3 tXX:1,2 tZX:0,2 tZY:1,0 tZZ:3,0
A27: 9 | B27: 04q_55125.qasm | C27: 4 | D27: 5 | E27: 5 | F27: 0.20000194 | G27: TRUE | H27: QPerm:3,2,0,1 H:0 H:1 HS:3 tXY:2,3 tZZ:3,0 tXX:3,1 tZY:2,1 tZY:1,0
A28: 10 | B28: 04q_99346.qasm | C28: 4 | D28: 5 | E28: 3 | F28: 0.21846146 | G28: TRUE | H28: HSH:0 S:1 H:2 tXY:0,2 tZX:3,2 tZZ:0,1 tZX:2,1 tXX:0,3
A29: 11 | B29: 05q_05306.qasm | C29: 5 | D29: 8 | E29: 5 | F29: 2.7661903 | G29: TRUE | H29: QPerm:4,1,2,3,0 S:0 H:1 H:2 H:3 HSH:4 tZZ:4,0 tZY:4,2 tYY:0,1 tXX:1,4 tXZ:2,3 tYY:2,4 tZY:0,3 tYX:0,2
A30: 12 | B30: 05q_33936.qasm | C30: 5 | D30: 8 | E30: 5 | F30: 2.6938772 | G30: TRUE | H30: QPerm:0,3,1,2,4 H:0 S:2 H:3 tZZ:2,0 tXY:1,2 tZY:3,0 tYZ:1,4 tXX:1,0 tYX:0,2 tXX:4,3 tZZ:1,4
... A43: 25 | B43: 07q_99346.qasm | C43: 7 | D43: 14 | E43: 9 | F43: 12.46988 | G43: TRUE | H43: QPerm:5,4,2,3,1,6,0 H:0 HS:1 HS:2 HSH:3 HSH:4 HSH:5 HS:6 tXZ:5,3 tZZ:3,6 tXZ:6,5 tZZ:4,1 tYZ:4,3 tYZ:1,0 tYX:3,0 tZX:0,5 tYZ:5,1 tYX:6,1 tYY:2,4 tXZ:0,4 tYX:1,2 tZZ:2,3

Sheet Sheet1a
A1: file: SATCircuits/Random-Clifford/tket_optimized_0cost_swaps
A2: method: astar
A3: submethod: 0
A4: mode: QC
A5: ixMin: 0
A6: ixMax: 0
A7: minDepth: 0
A8: wMax: 0
A9: hv: 1
A10: hr: 3
A11: hl: 1
A12: ht: 1
... A18: #########################################
A19: 1 | B19: 03q_05306.qasm | C19: 3 | D19: 2 | E19: 2 | F19: 0.26445427 | G19: TRUE | H19: QPerm:1,2,0 HS:0 HSH:1 S:2 tXZ:2,1 tXY:1,0
A20: 2 | B20: 03q_33936.qasm | C20: 3 | D20: 3 | E20: 3 | F20: 0.005208969 | G20: TRUE | H20: HSH:0 SH:2 tYX:0,2 tXY:2,1 tXZ:0,1
A21: 3 | B21: 03q_50494.qasm | C21: 3 | D21: 3 | E21: 3 | F21: 0.00497927 | G21: TRUE | H21: QPerm:1,2,0 S:0 HSH:1 HS:2 tYX:0,2 tXZ:2,1 tZX:0,1
A22: 4 | B22: 03q_55125.qasm | C22: 3 | D22: 3 | E22: 3 | F22: 0.005353959 | G22: TRUE | H22: QPerm:2,1,0 SH:0 S:1 HSH:2 tYY:0,1 tZY:2,1 tZX:0,2
A23: 5 | B23: 03q_99346.qasm | C23: 3 | D23: 3 | E23: 3 | F23: 0.004966357 | G23: TRUE | H23: QPerm:2,1,0 HSH:0 H:1 tZZ:2,0 tZZ:1,2 tXY:0,1
A24: 6 | B24: 04q_05306.qasm | C24: 4 | D24: 5 | E24: 5 | F24: 0.22933948 | G24: TRUE | H24: QPerm:0,1,3,2 SH:0 S:1 SH:2 tZY:1,2 tYX:3,2 tZZ:2,0 tXY:0,1 tZY:3,0
A25: 7 | B25: 04q_33936.qasm | C25: 4 | D25: 5 | E25: 5 | F25: 0.21881667 | G25: TRUE | H25: QPerm:3,1,0,2 HSH:0 H:1 HS:2 HSH:3 tZZ:1,3 tYX:3,2 tXX:0,3 tXZ:1,0 tYY:1,2
A26: 8 | B26: 04q_50494.qasm | C26: 4 | D26: 4 | E26: 4 | F26: 0.009019647 | G26: TRUE | H26: QPerm:1,3,0,2 HS:0 H:1 SH:2 HSH:3 tXX:1,2 tZX:0,2 tZY:1,0 tZZ:3,0
A27: 9 | B27: 04q_55125.qasm | C27: 4 | D27: 5 | E27: 5 | F27: 0.21512024 | G27: TRUE | H27: QPerm:3,2,0,1 H:0 H:1 HS:3 tXY:2,3 tZZ:3,0 tXX:3,1 tZY:2,1 tZY:1,0
A28: 10 | B28: 04q_99346.qasm | C28: 4 | D28: 5 | E28: 3 | F28: 0.23084293 | G28: TRUE | H28: HSH:0 S:1 H:2 tXY:0,2 tZX:3,2 tZZ:0,1 tZX:2,1 tXX:0,3
A29: 11 | B29: 05q_05306.qasm | C29: 5 | D29: 8 | E29: 5 | F29: 20.645562 | G29: TRUE | H29: QPerm:3,0,2,4,1 S:0 HS:1 H:3 S:4 tZZ:2,4 tXY:4,0 tYX:3,2 tXZ:3,1 tZY:0,3 tYZ:2,4 tXZ:2,3 tYY:1,4
A30: 12 | B30: 05q_33936.qasm | C30: 5 | D30: 8 | E30: 5 | F30: 19.621635 | G30: TRUE | H30: QPerm:0,3,1,2,4 H:0 HSH:1 S:2 H:3 HSH:4 tZZ:2,0 tXY:1,2 tZY:3,0 tYZ:1,4 tXX:3,1 tXX:4,0 tYY:1,4 tYX:0,2
... A43: 25 | B43: 07q_99346.qasm | C43: 7 | D43: 14 | E43: 10 | F43: 118.10673 | G43: TRUE | H43: QPerm:3,2,4,6,0,1,5 HSH:0 H:3 HSH:4 S:5 H:6 tZZ:3,6 tYX:3,4 tYX:3,2 tXY:0,4 tYX:0,6 tYX:2,0 tZX:2,5 tXY:3,5 tXX:1,0 tZX:0,2 tZZ:2,1 tXX:0,4 tYZ:0,3 tXY:0,6

Sheet Sheet2
A1: file: SATCircuits/Random-Clifford/tket_optimized_0cost_swaps
A2: method: greedy
A3: submethod: 0
A4: mode: QC
A5: ixMin: 0
A6: ixMax: 0
A7: minDepth: 0
A8: wMax: 0
A9: hv: 1
A10: hr: 3
A11: hl: 1
A12: ht: 1
... A18: #########################################
A19: 1 | B19: 03q_05306.qasm | C19: 3 | D19: 2 | E19: 2 | F19: 0.30444326 | G19: TRUE | H19: QPerm:1,2,0 HS:0 HSH:1 S:2 tZX:1,2 tXY:1,0
A20: 2 | B20: 03q_33936.qasm | C20: 3 | D20: 3 | E20: 3 | F20: 0.006433622 | G20: TRUE | H20: HSH:0 SH:2 tXY:2,1 tXY:2,0 tZX:1,0
A21: 3 | B21: 03q_50494.qasm | C21: 3 | D21: 3 | E21: 3 | F21: 0.006156026 | G21: TRUE | H21: QPerm:1,2,0 S:0 HSH:1 HS:2 tXY:2,0 tZX:1,2 tZX:0,1
A22: 4 | B22: 03q_55125.qasm | C22: 3 | D22: 3 | E22: 3 | F22: 0.006390825 | G22: TRUE | H22: QPerm:2,1,0 SH:0 S:1 HSH:2 tYY:0,1 tZY:2,1 tZX:0,2
A23: 5 | B23: 03q_99346.qasm | C23: 3 | D23: 3 | E23: 3 | F23: 0.006314003 | G23: TRUE | H23: QPerm:2,1,0 HSH:0 H:1 tZZ:1,2 tZZ:0,2 tXY:0,1
A24: 6 | B24: 04q_05306.qasm | C24: 4 | D24: 5 | E24: 5 | F24: 0.019167533 | G24: TRUE | H24: QPerm:0,1,3,2 SH:0 S:1 SH:2 tZY:1,2 tXY:2,3 tZZ:0,2 tXY:0,1 tZY:3,0
A25: 7 | B25: 04q_33936.qasm | C25: 4 | D25: 5 | E25: 3 | F25: 0.016144929 | G25: TRUE | H25: QPerm:3,0,1,2 H:0 H:1 HS:3 tZZ:2,3 tXY:1,3 tXX:0,2 tXY:3,0 tZZ:1,2
A26: 8 | B26: 04q_50494.qasm | C26: 4 | D26: 4 | E26: 4 | F26: 0.010180927 | G26: TRUE | H26: QPerm:1,3,0,2 HS:0 H:1 SH:2 HSH:3 tXX:1,2 tZX:0,2 tZY:1,0 tZZ:0,3
A27: 9 | B27: 04q_55125.qasm | C27: 4 | D27: 6 | E27: 5 | F27: 0.019910293 | G27: TRUE | H27: QPerm:3,2,0,1 S:0 SH:1 H:2 HS:3 tYY:0,2 tXY:2,3 tYY:1,3 tZY:3,0 tZX:2,1 tZZ:0,1
A28: 10 | B28: 04q_99346.qasm | C28: 4 | D28: 5 | E28: 3 | F28: 0.016706432 | G28: TRUE | H28: HSH:0 S:1 H:2 tXY:0,2 tZX:3,2 tZZ:0,1 tZX:2,1 tXX:0,3
A29: 11 | B29: 05q_05306.qasm | C29: 5 | D29: 8 | E29: 6 | F29: 0.035736832 | G29: TRUE | H29: QPerm:2,0,1,3,4 HS:0 H:2 HS:3 S:4 tXX:3,4 tZY:0,3 tZZ:2,4 tXY:0,4 tYX:2,3 tZY:1,4 tXY:1,3 tZX:0,3
A30: 12 | B30: 05q_33936.qasm | C30: 5 | D30: 9 | E30: 9 | F30: 0.046923149 | G30: TRUE | H30: QPerm:1,4,3,0,2 SH:1 SH:2 SH:3 S:4 tZY:0,2 tZY:0,1 tZX:0,3 tXY:4,3 tZX:4,0 tZX:1,4 tXY:3,1 tZX:1,2 tXX:0,2
... A43: 25 | B43: 07q_99346.qasm | C43: 7 | D43: 16 | E43: 12 | F43: 0.14270985 | G43: TRUE | H43: QPerm:4,6,2,3,1,0,5 S:0 HS:1 HS:3 H:4 HSH:5 HSH:6 tYY:1,6 tZY:3,1 tZZ:3,4 tXX:0,4 tXY:1,0 tZX:0,3 tXY:6,3 tZZ:3,5 tXY:3,1 tXY:5,0 tXZ:6,1 tXY:0,6 tXY:2,4 tZX:3,2 tYY:1,2 tXZ:0,4

Sheet Sheet3
A1: file: SATCircuits/Random-Clifford/tket_optimized_0cost_swaps
A2: method: qiskit
A3: submethod: 1
A4: mode: QC
A5: ixMin: 0
A6: ixMax: 0
A7: minDepth: 0
A8: wMax: 0
A9: hv: 1
A10: hr: 3
A11: hl: 1
A12: ht: 1
... A18: #########################################
A19: 1 | B19: 03q_05306.qasm | C19: 3 | D19: 5 | E19: 5 | F19: 0.0022555813 | H19: Z:1 H:2 SDG:2 H:2 SDG:2 H:1 SDG:1 H:1 CX:2,1 H:0 CX:0,2 H:0 SDG:0 CX:2,0 CX:1,0 SDG:0 CX:0,1
A20: 2 | B20: 03q_33936.qasm | C20: 3 | D20: 5 | E20: 5 | F20: 0.0019067824 | H20: X:1 Z:1 Z:0 H:2 SDG:2 H:2 SDG:2 H:1 CX:1,2 H:1 CX:2,1 SDG:1 CX:2,1 SDG:1 SWAP:2,1 SDG:0 CX:1,0 CX:0,2
A21: 3 | B21: 03q_50494.qasm | C21: 3 | D21: 8 | E21: 8 | F21: 0.0010847449 | H21: X:2 Z:2 X:1 H:1 SDG:1 CX:1,2 H:1 CX:2,1 SDG:1 CX:2,1 SDG:1 CX:1,2 H:0 SDG:0 CX:0,2 H:0 SDG:0 CX:2,0 CX:1,0 SDG:0 CX:0,2
A22: 4 | B22: 03q_55125.qasm | C22: 3 | D22: 7 | E22: 7 | F22: 0.0010203123 | H22: X:1 Z:0 H:2 SDG:2 H:2 CX:2,1 SDG:1 CX:2,1 SDG:1 H:1 H:0 SDG:0 CX:0,2 H:0 CX:2,0 CX:1,0 SDG:0 CX:2,0 CX:1,0 SWAP:1,0
A23: 5 | B23: 03q_99346.qasm | C23: 3 | D23: 7 | E23: 7 | F23: 0.00092547387 | H23: Z:2 X:1 Z:0 H:2 SDG:2 H:2 H:1 CX:1,2 H:1 CX:2,1 CX:1,2 CX:2,0 CX:1,0 SDG:0 CX:2,0 CX:1,0 SDG:0 SWAP:2,0
A24: 6 | B24: 04q_05306.qasm | C24: 4 | D24: 11 | E24: 11 | F24: 0.0011087954 | H24: Z:2 X:1 H:2 SDG:2 H:2 CX:3,2 H:1 CX:1,3 H:1 CX:2,1 SDG:1 CX:3,1 CX:2,1 SDG:1 CX:1,3 CX:3,0 CX:2,0 CX:1,0 SDG:0 CX:1,0 SDG:0 CX:0,1
A25: 7 | B25: 04q_33936.qasm | C25: 4 | D25: 11 | E25: 11 | F25: 0.0011905283 | H25: X:3 X:2 Z:2 Z:1 Z:0 H:3 H:2 SDG:2 CX:2,3 H:2 CX:3,2 SDG:2 CX:3,2 H:1 CX:1,3 CX:1,2 H:1 SDG:1 H:0 SDG:0 CX:0,1 H:0 CX:3,0 CX:1,0 SDG:0 CX:3,0 CX:2,0 CX:0,1
A26: 8 | B26: 04q_50494.qasm | C26: 4 | D26: 7 | E26: 6 | F26: 0.001270771 | H26: X:3 Z:2 Z:1 X:0 Z:0 H:3 SDG:3 H:3 H:2 SDG:2 H:2 CX:3,2 SDG:2 CX:3,2 SWAP:3,2 H:1 SDG:1 CX:1,2 H:1 CX:3,1 SDG:1 SWAP:2,1 H:0 CX:0,2 H:0 SDG:0 CX:2,0 CX:1,0 SDG:0 SWAP:1,0
A27: 9 | B27: 04q_55125.qasm | C27: 4 | D27: 13 | E27: 12 | F27: 0.0010872111 | H27: Z:3 Z:2 Z:1 X:0 CX:2,3 H:1 SDG:1 CX:1,3 H:1 CX:3,1 CX:2,1 SDG:1 CX:1,3 CX:1,2 H:0 CX:0,3 CX:0,2 CX:0,1 H:0 CX:1,0 SDG:0 CX:2,0 SDG:0 CX:0,2 CX:0,1
A28: 10 | B28: 04q_99346.qasm | C28: 4 | D28: 8 | E28: 8 | F28: 0.0011371896 | H28: Z:2 X:1 Z:1 Z:0 H:3 SDG:3 H:3 H:3 H:2 CX:2,3 H:2 CX:3,2 SDG:2 CX:2,3 H:1 CX:1,3 H:1 SDG:1 CX:3,0 SDG:0 CX:2,0 CX:1,0 CX:0,3 SWAP:1,0
A29: 11 | B29: 05q_05306.qasm | C29: 5 | D29: 17 | E29: 17 | F29: 0.0018498003 | H29: Z:1 X:0 Z:0 H:4 SDG:4 H:4 SDG:4 H:3 SDG:3 H:3 CX:4,2 SDG:2 CX:3,2 CX:2,4 SWAP:3,2 H:1 CX:1,4 H:1 CX:3,1 CX:2,1 SDG:1 CX:4,1 CX:3,1 CX:1,3 CX:1,2 H:0 CX:0,1 H:0 CX:4,0 CX:3,0 CX:1,0 SDG:0 CX:4,0 CX:3,0 CX:1,0 SWAP:4,0
A30: 12 | B30: 05q_33936.qasm | C30: 5 | D30: 20 | E30: 20 | F30: 0.0016954988 | H30: X:4 Z:3 X:2 Z:1 X:0 SDG:4 H:3 SDG:3 H:3 CX:4,3 SDG:3 CX:4,3 H:2 CX:2,4 H:2 SDG:2 CX:2,4 SWAP:3,2 H:1 SDG:1 CX:1,2 H:1 CX:3,1 SDG:1 CX:4,1 SDG:1 CX:1,4 CX:1,3 CX:1,2 H:0 CX:0,2 H:0 CX:4,0 CX:3,0 CX:1,0 SDG:0 CX:4,0 CX:3,0 CX:2,0 CX:1,0 SDG:0 CX:0,4 CX:0,3 SWAP:2,0
